Workbook

Sheet 記入方法
B1: FY27 目標設定シート（Corporate Planning）記入方法 ドラフト v0.1
B3: このシートの目的 | C3: 期初にコンピテンシー目標（1年後・3年後）とKPI目標（L4以上）を立て、カウンセラーと合意します。期末は同じシートで振り返ります。
B4: シートの構成 | C4: 記入方法／目標設定シート（記入用）／記入例_L1／記入例_L4／マスタ（参照用。編集しない）
B5: タイトルの表記 | C5: 本体HRのタイトルとINTS等級を併記します。書式は「機能名＋本体タイトル（INTS：等級）」。例：HRチーフ（INTS：Consultant）、FINマネジャー（INTS：Manager）。処遇・評価はINTS等級で運用し、本体の職位・バンドは読み替えに使います。
B6: 入力するセル | C6: 黄色のセルだけを記入します。灰色のセルは、レベルと主担当領域を選ぶと自動で表示されます。
B7: 手順1 | C7: 前回の評価FBシートの「期待」と、自分のレベルの期待水準（評価3）を確認する
B8: 手順2 | C8: ①基本情報で、レベル（L1〜L6）と主担当領域（6領域）をプルダウンで選ぶ
B9: 手順3 | C9: ②短期目標を書く。サマリーは必須。各観点は【目標】【行動計画】【成果イメージ】に分けて書き、ウェイトの大きい観点ほど具体的に書く。L1〜L3は「専門領域の育成目標」も書く
B10: 手順4 | C10: ③中長期目標を書く。目指すレベル（標準は1つ上）を選び、3年後の姿を書く
B11: 手順5 | C11: ④KPI目標を書く（L4以上）。最低ライン・目標・ストレッチの3段階で書き、ウェイトの合計を100%にする
B12: 手順6 | C12: カウンセラーと面談（30〜45分）し、⑥合意欄の記入後に提出する。⑤期末の振り返りは空欄のまま提出する
B13: 評価の付け方（5・3・1） | C13: 3＝自分のレベルの期待水準を満たす／5＝1つ上のレベルの水準を安定して発揮／1＝1つ下のレベルの水準にとどまる（2・4は中間）。各観点の評価×ウェイトの合計で算出します。
B14: 専門性の扱い | C14: 評価ウェイトはL4以上だけに置きます。L1〜L3は、主担当領域の「専門領域スキル」を育成目標として管理します。
B15: 位置づけ | C15: 本シートはドラフトです。レベル体系・ウェイト・タイトル名称は、福島Dirとの合意と本体HRとの読み替え確認の後に確定します（FY27期中の1on1で試行し、FY28評価準備で正式化する案）。
B17: 凡例
B18: 記入欄 | C18: 本人（合意欄はカウンセラー）が記入する
B19: 自動表示 | C19: マスタから自動で表示される。上書きしない
B21: 参照資料 | C21: CorpPlanning_タイトル別コンピテンシー定義_ドラフト_v02、INTS_HRキャリアパス設計_v031、コンピテンシー定義書 Corporate Planning Ver.0.14.3、FY27 目標設定ガイド V1.3（Consulting）、成長目標シート V1.8

Sheet 目標設定シート
A1: FY27 目標設定シート（Corporate Planning）
A2: 黄色＝本人が記入 ｜ 灰色＝レベル・主担当領域を選ぶと自動表示 ｜ 表記は「本体タイトル（INTS：等級）」の併記
A4: ① 基本情報
B5: 氏名
B6: レベル | F6: =IF($C$6="","","評価の比率：コンピテンシー "&TEXT(INDEX(マスタ!$J$3:$J$8,MATCH($C$6,マスタ!$A$3:$A$8,0)),"0%")&"／KPI目標："&INDEX(マスタ!$I$3:$I$8,MATCH($C$6,マスタ!$A$3:$A$8,0)))
B7: タイトル（併記） | C7: =IF(OR($C$6="",$C$9=""),"",INDEX(マスタ!$B$36:$B$41,MATCH($C$9,マスタ!$A$36:$A$41,0))&INDEX(マスタ!$B$3:$B$8,MATCH($C$6,マスタ!$A$3:$A$8,0))&"（INTS："&INDEX(マスタ!$F$3:$F$8,MATCH($C$6,マスタ!$A$3:$A$8,0))&"）")
B8: 本体の職位・バンド | C8: =IF($C$6="","",INDEX(マスタ!$D$3:$D$8,MATCH($C$6,マスタ!$A$3:$A$8,0))&"（"&INDEX(マスタ!$E$3:$E$8,MATCH($C$6,マスタ!$A$3:$A$8,0))&"）")
B9: 主担当領域
B10: マネジメントスパン | C10: =IF($C$6="","",INDEX(マスタ!$G$3:$G$8,MATCH($C$6,マスタ!$A$3:$A$8,0))&"／指導："&INDEX(マスタ!$H$3:$H$8,MATCH($C$6,マスタ!$A$3:$A$8,0)))
B11: カウンセラー氏名
B12: カウンセラーのレベル
B13: カウンセラーのタイトル | C13: =IF($C$12="","",INDEX(マスタ!$B$3:$B$8,MATCH($C$12,マスタ!$A$3:$A$8,0))&"（INTS："&INDEX(マスタ!$F$3:$F$8,MATCH($C$12,マスタ!$A$3:$A$8,0))&"）")
B14: 作成日
B15: 作成タイミング | C15: 期初
A17: ② コンピテンシー短期目標（1年後の目安） ※サマリーは必須。各項目は該当する場合に記入し、ウェイトの大きい項目は具体的に書く
B18: サマリー（必須）
A19: 提供価値 | B19: 評価観点 | C19: ウェイト | D19: 期待水準（評価3） | E19: 【目標】 | F19: 【行動計画】 | G19: 【成果イメージ】
A20: クライアントバリュー | B20: 問題解決能力 | C20: =IF($C$6="","",INDEX(マスタ!$B$12:$G$20,MATCH($B20,マスタ!$A$12:$A$20,0),MATCH($C$6,マスタ!$A$3:$A$8,0))) | D20: =IF($C$6="","",INDEX(マスタ!$B$24:$G$32,MATCH($B20,マスタ!$A$24:$A$32,0),MATCH($C$6,マスタ!$A$3:$A$8,0)))
B21: タスク管理・マネジメント力 | C21: =IF($C$6="","",INDEX(マスタ!$B$12:$G$20,MATCH($B21,マスタ!$A$12:$A$20,0),MATCH($C$6,マスタ!$A$3:$A$8,0))) | D21: =IF($C$6="","",INDEX(マスタ!$B$24:$G$32,MATCH($B21,マスタ!$A$24:$A$32,0),MATCH($C$6,マスタ!$A$3:$A$8,0)))
B22: 口頭コミュニケーション | C22: =IF($C$6="","",INDEX(マスタ!$B$12:$G$20,MATCH($B22,マスタ!$A$12:$A$20,0),MATCH($C$6,マスタ!$A$3:$A$8,0))) | D22: =IF($C$6="","",INDEX(マスタ!$B$24:$G$32,MATCH($B22,マスタ!$A$24:$A$32,0),MATCH($C$6,マスタ!$A$3:$A$8,0)))
B23: 文書コミュニケーション | C23: =IF($C$6="","",INDEX(マスタ!$B$12:$G$20,MATCH($B23,マスタ!$A$12:$A$20,0),MATCH($C$6,マスタ!$A$3:$A$8,0))) | D23: =IF($C$6="","",INDEX(マスタ!$B$24:$G$32,MATCH($B23,マスタ!$A$24:$A$32,0),MATCH($C$6,マスタ!$A$3:$A$8,0)))
B24: 専門性 | C24: =IF($C$6="","",INDEX(マスタ!$B$12:$G$20,MATCH($B24,マスタ!$A$12:$A$20,0),MATCH($C$6,マスタ!$A$3:$A$8,0))) | D24: =IF($C$6="","",INDEX(マスタ!$B$24:$G$32,MATCH($B24,マスタ!$A$24:$A$32,0),MATCH($C$6,マスタ!$A$3:$A$8,0)))
A25: ピープルバリュー | B25: 機能人材の確保・育成貢献 | C25: =IF($C$6="","",INDEX(マスタ!$B$12:$G$20,MATCH($B25,マスタ!$A$12:$A$20,0),MATCH($C$6,マスタ!$A$3:$A$8,0))) | D25: =IF($C$6="","",INDEX(マスタ!$B$24:$G$32,MATCH($B25,マスタ!$A$24:$A$32,0),MATCH($C$6,マスタ!$A$3:$A$8,0)))
B26: 関係構築・連携 | C26: =IF($C$6="","",INDEX(マスタ!$B$12:$G$20,MATCH($B26,マスタ!$A$12:$A$20,0),MATCH($C$6,マスタ!$A$3:$A$8,0))) | D26: =IF($C$6="","",INDEX(マスタ!$B$24:$G$32,MATCH($B26,マスタ!$A$24:$A$32,0),MATCH($C$6,マスタ!$A$3:$A$8,0)))
A27: ファームバリュー | B27: ファームビルディング | C27: =IF($C$6="","",INDEX(マスタ!$B$12:$G$20,MATCH($B27,マスタ!$A$12:$A$20,0),MATCH($C$6,マスタ!$A$3:$A$8,0))) | D27: =IF($C$6="","",INDEX(マスタ!$B$24:$G$32,MATCH($B27,マスタ!$A$24:$A$32,0),MATCH($C$6,マスタ!$A$3:$A$8,0)))
B28: 経営価値創出力 | C28: =IF($C$6="","",INDEX(マスタ!$B$12:$G$20,MATCH($B28,マスタ!$A$12:$A$20,0),MATCH($C$6,マスタ!$A$3:$A$8,0))) | D28: =IF($C$6="","",INDEX(マスタ!$B$24:$G$32,MATCH($B28,マスタ!$A$24:$A$32,0),MATCH($C$6,マスタ!$A$3:$A$8,0)))
B29: 合計 | C29: =SUM(C20:C28) -> 0 | D29: =IF($C$6="","",IF(ROUND(C29,4)=1,"","ウェイト合計が100%になっていません"))
B30: 専門領域の育成目標 （L1〜L3は必須） | D30: =IF(OR($C$6="",$C$9=""),"","現レベル："&INDEX(マスタ!$C$36:$H$41,MATCH($C$9,マスタ!$A$36:$A$41,0),MATCH($C$6,マスタ!$A$3:$A$8,0))&CHAR(10)&"次のレベル："&INDEX(マスタ!$C$36:$H$41,MATCH($C$9,マスタ!$A$36:$A$41,0),MIN(MATCH($C$6,マスタ!$A$3:$A$8,0)+1,6)))
B31: その他（個人目標など） | D31: 資格取得・業務知識など（任意）
A33: ③ コンピテンシー中長期目標（3年後の目安） ※サマリーは必須。目指すレベルでの3年後の姿を書く
B34: 目指すレベル | D34: =IF($C$34="","",INDEX(マスタ!$B$3:$B$8,MATCH($C$34,マスタ!$A$3:$A$8,0))&"（INTS："&INDEX(マスタ!$F$3:$F$8,MATCH($C$34,マスタ!$A$3:$A$8,0))&"）／"&INDEX(マスタ!$D$3:$D$8,MATCH($C$34,マスタ!$A$3:$A$8,0)))
B35: サマリー（必須）
A36: 提供価値 | B36: 評価観点 | D36: 目指すレベルの期待水準（参考） | E36: 3年後の姿
A37: クライアントバリュー | B37: 問題解決能力 | D37: =IF($C$34="","",INDEX(マスタ!$B$24:$G$32,MATCH($B37,マスタ!$A$24:$A$32,0),MATCH($C$34,マスタ!$A$3:$A$8,0)))
B38: タスク管理・マネジメント力 | D38: =IF($C$34="","",INDEX(マスタ!$B$24:$G$32,MATCH($B38,マスタ!$A$24:$A$32,0),MATCH($C$34,マスタ!$A$3:$A$8,0)))
B39: 口頭コミュニケーション | D39: =IF($C$34="","",INDEX(マスタ!$B$24:$G$32,MATCH($B39,マスタ!$A$24:$A$32,0),MATCH($C$34,マスタ!$A$3:$A$8,0)))
B40: 文書コミュニケーション | D40: =IF($C$34="","",INDEX(マスタ!$B$24:$G$32,MATCH($B40,マスタ!$A$24:$A$32,0),MATCH($C$34,マスタ!$A$3:$A$8,0)))
B41: 専門性 | D41: =IF($C$34="","",INDEX(マスタ!$B$24:$G$32,MATCH($B41,マスタ!$A$24:$A$32,0),MATCH($C$34,マスタ!$A$3:$A$8,0)))
A42: ピープルバリュー | B42: 機能人材の確保・育成貢献 | D42: =IF($C$34="","",INDEX(マスタ!$B$24:$G$32,MATCH($B42,マスタ!$A$24:$A$32,0),MATCH($C$34,マスタ!$A$3:$A$8,0)))
B43: 関係構築・連携 | D43: =IF($C$34="","",INDEX(マスタ!$B$24:$G$32,MATCH($B43,マスタ!$A$24:$A$32,0),MATCH($C$34,マスタ!$A$3:$A$8,0)))
...

Sheet 記入例_L1
A1: FY27 目標設定シート（Corporate Planning） 記入例：L1
A2: 黄色＝本人が記入 ｜ 灰色＝レベル・主担当領域を選ぶと自動表示 ｜ 表記は「本体タイトル（INTS：等級）」の併記
A4: ① 基本情報
B5: 氏名 | C5: 院津 太郎（サンプル）
B6: レベル | C6: L1 | F6: =IF($C$6="","","評価の比率：コンピテンシー "&TEXT(INDEX(マスタ!$J$3:$J$8,MATCH($C$6,マスタ!$A$3:$A$8,0)),"0%")&"／KPI目標："&INDEX(マスタ!$I$3:$I$8,MATCH($C$6,マスタ!$A$3:$A$8,0))) -> 評価の比率：コンピテンシー 100%／KPI目標：対象外
B7: タイトル（併記） | C7: =IF(OR($C$6="",$C$9=""),"",INDEX(マスタ!$B$36:$B$41,MATCH($C$9,マスタ!$A$36:$A$41,0))&INDEX(マスタ!$B$3:$B$8,MATCH($C$6,マスタ!$A$3:$A$8,0))&"（INTS："&INDEX(マスタ!$F$3:$F$8,MATCH($C$6,マスタ!$A$3:$A$8,0))&"）") -> HRスタッフ／サブチーフ（INTS：Associate）
B8: 本体の職位・バンド | C8: =IF($C$6="","",INDEX(マスタ!$D$3:$D$8,MATCH($C$6,マスタ!$A$3:$A$8,0))&"（"&INDEX(マスタ!$E$3:$E$8,MATCH($C$6,マスタ!$A$3:$A$8,0))&"）") -> 社員・副主任（A01〜A03）
B9: 主担当領域 | C9: 人事・労務
B10: マネジメントスパン | C10: =IF($C$6="","",INDEX(マスタ!$G$3:$G$8,MATCH($C$6,マスタ!$A$3:$A$8,0))&"／指導："&INDEX(マスタ!$H$3:$H$8,MATCH($C$6,マスタ!$A$3:$A$8,0))) -> 1領域の定型業務（指示された範囲）／指導：なし
B11: カウンセラー氏名 | C11: 院都 花子（サンプル）
B12: カウンセラーのレベル | C12: L4
B13: カウンセラーのタイトル | C13: =IF($C$12="","",INDEX(マスタ!$B$3:$B$8,MATCH($C$12,マスタ!$A$3:$A$8,0))&"（INTS："&INDEX(マスタ!$F$3:$F$8,MATCH($C$12,マスタ!$A$3:$A$8,0))&"）") -> マネジャー（INTS：Manager）
B14: 作成日 | C14: 46321
B15: 作成タイミング | C15: 期初
A17: ② コンピテンシー短期目標（1年後の目安） ※サマリーは必須。各項目は該当する場合に記入し、ウェイトの大きい項目は具体的に書く
B18: サマリー（必須） | C18: L1 スタッフとして、人事・労務の定型業務（入退社・勤怠・社保の手続）を指示の範囲で期限内・ミスなく完了し、上長が安心して任せられるメンバーになる。重点観点の問題解決能力とタスク管理・マネジメント力で期待水準（評価3）を満たす。
A19: 提供価値 | B19: 評価観点 | C19: ウェイト | D19: 期待水準（評価3） | E19: 【目標】 | F19: 【行動計画】 | G19: 【成果イメージ】
A20: クライアントバリュー | B20: 問題解決能力 | C20: =IF($C$6="","",INDEX(マスタ!$B$12:$G$20,MATCH($B20,マスタ!$A$12:$A$20,0),MATCH($C$6,マスタ!$A$3:$A$8,0))) -> 0.2 | D20: =IF($C$6="","",INDEX(マスタ!$B$24:$G$32,MATCH($B20,マスタ!$A$24:$A$32,0),MATCH($C$6,マスタ!$A$3:$A$8,0))) -> 上長の支援で課題を整理する | E20: 指示されたタスクの目的を正確に理解し、課題と発生要因を整理したうえで解決策を示す | F20: 着手前に「論点・仮説・進め方」を簡潔に書き、上長とすり合わせる。Excel・AIツールを使って分析する | G20: すり合わせ後に大きな手戻りがない。期末の評価で問題解決能力3以上
B21: タスク管理・マネジメント力 | C21: =IF($C$6="","",INDEX(マスタ!$B$12:$G$20,MATCH($B21,マスタ!$A$12:$A$20,0),MATCH($C$6,マスタ!$A$3:$A$8,0))) -> 0.2 | D21: =IF($C$6="","",INDEX(マスタ!$B$24:$G$32,MATCH($B21,マスタ!$A$24:$A$32,0),MATCH($C$6,マスタ!$A$3:$A$8,0))) -> 支援を受け期日・品質を守る | E21: 担当タスクを期限から逆算して計画し、期日を守って一定品質で完了する | F21: タスク管理表を週次で自ら更新し、上長に共有する。遅れそうなときは早めに相談する | G21: 担当タスクの期限遅れがない。期末の評価でタスク管理・マネジメント力3以上
B22: 口頭コミュニケーション | C22: =IF($C$6="","",INDEX(マスタ!$B$12:$G$20,MATCH($B22,マスタ!$A$12:$A$20,0),MATCH($C$6,マスタ!$A$3:$A$8,0))) -> 0.1 | D22: =IF($C$6="","",INDEX(マスタ!$B$24:$G$32,MATCH($B22,マスタ!$A$24:$A$32,0),MATCH($C$6,マスタ!$A$3:$A$8,0))) -> 報・連・相を確実に行う | E22: 報・連・相を求められる前に自ら行い、質問に明確に答える | F22: 報告は「結論→理由→次のアクション」の型で短く伝える | G22: 上長から進捗を催促されることがない
B23: 文書コミュニケーション | C23: =IF($C$6="","",INDEX(マスタ!$B$12:$G$20,MATCH($B23,マスタ!$A$12:$A$20,0),MATCH($C$6,マスタ!$A$3:$A$8,0))) -> 0.1 | D23: =IF($C$6="","",INDEX(マスタ!$B$24:$G$32,MATCH($B23,マスタ!$A$24:$A$32,0),MATCH($C$6,マスタ!$A$3:$A$8,0))) -> 指示どおり正確に作成する | E23: 資料・案内文を、読み手が一目で理解できる形で正確に作る | F23: 冒頭に要点を置き、見出し・箇条書きを使う。提出前に誤字脱字と体裁をセルフチェックする | G23: 体裁・誤字脱字の修正指示がほとんど入らない
B24: 専門性 | C24: =IF($C$6="","",INDEX(マスタ!$B$12:$G$20,MATCH($B24,マスタ!$A$12:$A$20,0),MATCH($C$6,マスタ!$A$3:$A$8,0))) -> 0 | D24: =IF($C$6="","",INDEX(マスタ!$B$24:$G$32,MATCH($B24,マスタ!$A$24:$A$32,0),MATCH($C$6,マスタ!$A$3:$A$8,0))) -> －（育成目標で管理）
A25: ピープルバリュー | B25: 機能人材の確保・育成貢献 | C25: =IF($C$6="","",INDEX(マスタ!$B$12:$G$20,MATCH($B25,マスタ!$A$12:$A$20,0),MATCH($C$6,マスタ!$A$3:$A$8,0))) -> 0.1 | D25: =IF($C$6="","",INDEX(マスタ!$B$24:$G$32,MATCH($B25,マスタ!$A$24:$A$32,0),MATCH($C$6,マスタ!$A$3:$A$8,0))) -> フィードバックを受け改善する | E25: 期初に自らスキル開発目標を立て、フィードバックを改善に生かす | F25: 上長との1on1を月一回、自分から設定する | G25: 前回のFBで指摘された点が、期末までに改善している
B26: 関係構築・連携 | C26: =IF($C$6="","",INDEX(マスタ!$B$12:$G$20,MATCH($B26,マスタ!$A$12:$A$20,0),MATCH($C$6,マスタ!$A$3:$A$8,0))) -> 0.1 | D26: =IF($C$6="","",INDEX(マスタ!$B$24:$G$32,MATCH($B26,マスタ!$A$24:$A$32,0),MATCH($C$6,マスタ!$A$3:$A$8,0))) -> 指示の範囲で協力する | E26: 本体HRの担当者と、指示の範囲で協力して業務を進める | F26: 調整状況と懸念点を自ら上長・チームに共有する | G26: 本体HRとの手続の調整が、上長の介入なしで進む
A27: ファームバリュー | B27: ファームビルディング | C27: =IF($C$6="","",INDEX(マスタ!$B$12:$G$20,MATCH($B27,マスタ!$A$12:$A$20,0),MATCH($C$6,マスタ!$A$3:$A$8,0))) -> 0.1 | D27: =IF($C$6="","",INDEX(マスタ!$B$24:$G$32,MATCH($B27,マスタ!$A$24:$A$32,0),MATCH($C$6,マスタ!$A$3:$A$8,0))) -> ルールを理解し実践する | E27: 人事関連の規程・ルールを理解し、運用する側として正しく実践する | F27: 就業規則と関連規程を読み、担当手続の根拠を手順書に書き込む | G27: 担当手続で規程違反や差し戻しがない
B28: 経営価値創出力 | C28: =IF($C$6="","",INDEX(マスタ!$B$12:$G$20,MATCH($B28,マスタ!$A$12:$A$20,0),MATCH($C$6,マスタ!$A$3:$A$8,0))) -> 0.1 | D28: =IF($C$6="","",INDEX(マスタ!$B$24:$G$32,MATCH($B28,マスタ!$A$24:$A$32,0),MATCH($C$6,マスタ!$A$3:$A$8,0))) -> 精度・期限を守り完遂する | E28: 指示された人事データ・経営情報の収集・入力を、精度・期限を守って完了する | F28: 提出前にチェックリストで検算し、期日の2営業日前に提出する | G28: 上長の確認・修正なしで使える精度で提出できている
B29: 合計 | C29: =SUM(C20:C28) -> 1 | D29: =IF($C$6="","",IF(ROUND(C29,4)=1,"","ウェイト合計が100%になっていません"))
B30: 専門領域の育成目標 （L1〜L3は必須） | D30: =IF(OR($C$6="",$C$9=""),"","現レベル："&INDEX(マスタ!$C$36:$H$41,MATCH($C$9,マスタ!$A$36:$A$41,0),MATCH($C$6,マスタ!$A$3:$A$8,0))&CHAR(10)&"次のレベル："&INDEX(マスタ!$C$36:$H$41,MATCH($C$9,マスタ!$A$36:$A$41,0),MIN(MATCH($C$6,マスタ!$A$3:$A$8,0)+1,6))) -> 現レベル：入退社・勤怠・社保の手続 次のレベル：労務運用・評価の事務局 | E30: L2 チーフの水準である「労務運用・評価の事務局」業務の一部を担えるようにする | F30: 評価シートの回収・集計を担当し、手順書を作る | G30: 期末時点で、評価シートの回収・集計を一人で回せている
B31: その他（個人目標など） | D31: 資格取得・業務知識など（任意） | E31: 人事・労務の基礎知識を身につける | F31: 社内規程と労務の基礎研修を受講する | G31: 受講した内容を担当業務の手順書に反映している
A33: ③ コンピテンシー中長期目標（3年後の目安） ※サマリーは必須。目指すレベルでの3年後の姿を書く
B34: 目指すレベル | C34: L2 | D34: =IF($C$34="","",INDEX(マスタ!$B$3:$B$8,MATCH($C$34,マスタ!$A$3:$A$8,0))&"（INTS："&INDEX(マスタ!$F$3:$F$8,MATCH($C$34,マスタ!$A$3:$A$8,0))&"）／"&INDEX(マスタ!$D$3:$D$8,MATCH($C$34,マスタ!$A$3:$A$8,0))) -> チーフ（INTS：Consultant）／主任
B35: サマリー（必須） | C35: 3年後はL2 チーフ（INTS：Consultant）として、人事・労務の業務一式を自立して運用し、本体HRの担当者と自ら連携している。新メンバーのOJTも補助している。
A36: 提供価値 | B36: 評価観点 | D36: 目指すレベルの期待水準（参考） | E36: 3年後の姿
A37: クライアントバリュー | B37: 問題解決能力 | D37: =IF($C$34="","",INDEX(マスタ!$B$24:$G$32,MATCH($B37,マスタ!$A$24:$A$32,0),MATCH($C$34,マスタ!$A$3:$A$8,0))) -> 自ら仮説を立てて構造化する | E37: 担当業務の課題に自ら仮説を立て、構造化して解決策を示している
B38: タスク管理・マネジメント力 | D38: =IF($C$34="","",INDEX(マスタ!$B$24:$G$32,MATCH($B38,マスタ!$A$24:$A$32,0),MATCH($C$34,マスタ!$A$3:$A$8,0))) -> 逆算で計画し進捗を自発的に共有する | E38: 人事・労務の業務一式を逆算で計画し、進捗を自発的に共有している
B39: 口頭コミュニケーション | D39: =IF($C$34="","",INDEX(マスタ!$B$24:$G$32,MATCH($B39,マスタ!$A$24:$A$32,0),MATCH($C$34,マスタ!$A$3:$A$8,0))) -> 結論から簡潔に伝える | E39: 本体HR・社員への説明を結論から簡潔に行っている
B40: 文書コミュニケーション | D40: =IF($C$34="","",INDEX(マスタ!$B$24:$G$32,MATCH($B40,マスタ!$A$24:$A$32,0),MATCH($C$34,マスタ!$A$3:$A$8,0))) -> 要点を先に示す簡潔な文書を作る | E40: 手順書・案内文を要点が先に伝わる形で作っている
B41: 専門性 | D41: =IF($C$34="","",INDEX(マスタ!$B$24:$G$32,MATCH($B41,マスタ!$A$24:$A$32,0),MATCH($C$34,マスタ!$A$3:$A$8,0))) -> －（育成目標で管理）
A42: ピープルバリュー | B42: 機能人材の確保・育成貢献 | D42: =IF($C$34="","",INDEX(マスタ!$B$24:$G$32,MATCH($B42,マスタ!$A$24:$A$32,0),MATCH($C$34,マスタ!$A$3:$A$8,0))) -> 自ら成長目標を設定し学ぶ | E42: 自ら成長目標を立てて学び、新メンバーのOJTを補助している
B43: 関係構築・連携 | D43: =IF($C$34="","",INDEX(マスタ!$B$24:$G$32,MATCH($B43,マスタ!$A$24:$A$32,0),MATCH($C$34,マスタ!$A$3:$A$8,0))) -> 本体の担当者と自ら連携する | E43: 本体HRの各チームと自ら連携し、窓口を担っている
...

Sheet 記入例_L4
A1: FY27 目標設定シート（Corporate Planning） 記入例：L4
A2: 黄色＝本人が記入 ｜ 灰色＝レベル・主担当領域を選ぶと自動表示 ｜ 表記は「本体タイトル（INTS：等級）」の併記
A4: ① 基本情報
B5: 氏名 | C5: 院津 花子（サンプル）
B6: レベル | C6: L4 | F6: =IF($C$6="","","評価の比率：コンピテンシー "&TEXT(INDEX(マスタ!$J$3:$J$8,MATCH($C$6,マスタ!$A$3:$A$8,0)),"0%")&"／KPI目標："&INDEX(マスタ!$I$3:$I$8,MATCH($C$6,マスタ!$A$3:$A$8,0))) -> 評価の比率：コンピテンシー 70%／KPI目標：非財務KPI（評価全体の30%）
B7: タイトル（併記） | C7: =IF(OR($C$6="",$C$9=""),"",INDEX(マスタ!$B$36:$B$41,MATCH($C$9,マスタ!$A$36:$A$41,0))&INDEX(マスタ!$B$3:$B$8,MATCH($C$6,マスタ!$A$3:$A$8,0))&"（INTS："&INDEX(マスタ!$F$3:$F$8,MATCH($C$6,マスタ!$A$3:$A$8,0))&"）") -> CPマネジャー（INTS：Manager）
B8: 本体の職位・バンド | C8: =IF($C$6="","",INDEX(マスタ!$D$3:$D$8,MATCH($C$6,マスタ!$A$3:$A$8,0))&"（"&INDEX(マスタ!$E$3:$E$8,MATCH($C$6,マスタ!$A$3:$A$8,0))&"）") -> 課長（A09）
B9: 主担当領域 | C9: 経営企画・業績管理
B10: マネジメントスパン | C10: =IF($C$6="","",INDEX(マスタ!$G$3:$G$8,MATCH($C$6,マスタ!$A$3:$A$8,0))&"／指導："&INDEX(マスタ!$H$3:$H$8,MATCH($C$6,マスタ!$A$3:$A$8,0))) -> 2〜3領域の統括／指導：1チーム（2〜4名）
B11: カウンセラー氏名 | C11: 院都 一郎（サンプル）
B12: カウンセラーのレベル | C12: L6
B13: カウンセラーのタイトル | C13: =IF($C$12="","",INDEX(マスタ!$B$3:$B$8,MATCH($C$12,マスタ!$A$3:$A$8,0))&"（INTS："&INDEX(マスタ!$F$3:$F$8,MATCH($C$12,マスタ!$A$3:$A$8,0))&"）") -> ディレクター（INTS：Director）
B14: 作成日 | C14: 46321
B15: 作成タイミング | C15: 期初
A17: ② コンピテンシー短期目標（1年後の目安） ※サマリーは必須。各項目は該当する場合に記入し、ウェイトの大きい項目は具体的に書く
B18: サマリー（必須） | C18: L4 マネジャーとして、経営企画・業績管理と経理・財務の2領域を統括し、経営資料の品質とKPIの整合を自律的に管理する。重点観点（各15%）の問題解決能力・タスク管理・マネジメント力・ファームビルディングで期待水準（評価3）を満たし、L1〜L2のメンバーを定常業務を単独で担える水準に育てる。
A19: 提供価値 | B19: 評価観点 | C19: ウェイト | D19: 期待水準（評価3） | E19: 【目標】 | F19: 【行動計画】 | G19: 【成果イメージ】
A20: クライアントバリュー | B20: 問題解決能力 | C20: =IF($C$6="","",INDEX(マスタ!$B$12:$G$20,MATCH($B20,マスタ!$A$12:$A$20,0),MATCH($C$6,マスタ!$A$3:$A$8,0))) -> 0.15 | D20: =IF($C$6="","",INDEX(マスタ!$B$24:$G$32,MATCH($B20,マスタ!$A$24:$A$32,0),MATCH($C$6,マスタ!$A$3:$A$8,0))) -> 複数領域の論点設定・分析をリードする | E20: 担当テーマの論点設定と仮説構築を、最小限の上長の指導で行う | F20: テーマ着手時に論点ツリーを作り、初回レビューで合意する | G20: 論点設計が初回レビューで合意され、大きな手戻りがない
B21: タスク管理・マネジメント力 | C21: =IF($C$6="","",INDEX(マスタ!$B$12:$G$20,MATCH($B21,マスタ!$A$12:$A$20,0),MATCH($C$6,マスタ!$A$3:$A$8,0))) -> 0.15 | D21: =IF($C$6="","",INDEX(マスタ!$B$24:$G$32,MATCH($B21,マスタ!$A$24:$A$32,0),MATCH($C$6,マスタ!$A$3:$A$8,0))) -> 複数領域の計画・予算・品質を管理する | E21: 担当2領域の計画・予算・品質を管理し、主要な業務を期日どおりに完了する | F21: 期初にWBSを作り、週次で進捗とリスクを上長に報告する | G21: MBRと月次決算の主要マイルストーンが期日どおりに完了している
B22: 口頭コミュニケーション | C22: =IF($C$6="","",INDEX(マスタ!$B$12:$G$20,MATCH($B22,マスタ!$A$12:$A$20,0),MATCH($C$6,マスタ!$A$3:$A$8,0))) -> 0.08 | D22: =IF($C$6="","",INDEX(マスタ!$B$24:$G$32,MATCH($B22,マスタ!$A$24:$A$32,0),MATCH($C$6,マスタ!$A$3:$A$8,0))) -> 事業部門・本体と合意形成する | E22: 事業部門・本体との定例会を自ら主導し、合意を形成する | F22: 定例会のファシリテーションを毎回担当する | G22: 定例会が意思決定の場として機能している
B23: 文書コミュニケーション | C23: =IF($C$6="","",INDEX(マスタ!$B$12:$G$20,MATCH($B23,マスタ!$A$12:$A$20,0),MATCH($C$6,マスタ!$A$3:$A$8,0))) -> 0.07 | D23: =IF($C$6="","",INDEX(マスタ!$B$24:$G$32,MATCH($B23,マスタ!$A$24:$A$32,0),MATCH($C$6,マスタ!$A$3:$A$8,0))) -> チームの成果物の品質に責任を持つ | E23: チームの成果物（経営資料・規程案）の品質に責任を持つ | F23: 資料のストーリーを自ら設計し、メンバーの資料をレビューする | G23: チームの資料が上長の大きな修正なしで承認されている
B24: 専門性 | C24: =IF($C$6="","",INDEX(マスタ!$B$12:$G$20,MATCH($B24,マスタ!$A$12:$A$20,0),MATCH($C$6,マスタ!$A$3:$A$8,0))) -> 0.1 | D24: =IF($C$6="","",INDEX(マスタ!$B$24:$G$32,MATCH($B24,マスタ!$A$24:$A$32,0),MATCH($C$6,マスタ!$A$3:$A$8,0))) -> 主担当領域で市場水準の専門性を持つ | E24: 経営企画・業績管理で市場水準の専門性を持ち、経営課題の解決に生かす | F24: 予実管理・KPI設計の手法を四半期ごとにチームへ共有する | G24: 専門性を生かした提言が経営会議で採用されている
A25: ピープルバリュー | B25: 機能人材の確保・育成貢献 | C25: =IF($C$6="","",INDEX(マスタ!$B$12:$G$20,MATCH($B25,マスタ!$A$12:$A$20,0),MATCH($C$6,マスタ!$A$3:$A$8,0))) -> 0.1 | D25: =IF($C$6="","",INDEX(マスタ!$B$24:$G$32,MATCH($B25,マスタ!$A$24:$A$32,0),MATCH($C$6,マスタ!$A$3:$A$8,0))) -> メンバーの育成計画・キャリア支援を行う | E25: メンバーの育成計画を作り、キャリアを支援する | F25: メンバーと週一回の1on1を行い、評価期間ごとに評価シートとFB面談を行う | G25: メンバーの評価が前回より上がっている
B26: 関係構築・連携 | C26: =IF($C$6="","",INDEX(マスタ!$B$12:$G$20,MATCH($B26,マスタ!$A$12:$A$20,0),MATCH($C$6,マスタ!$A$3:$A$8,0))) -> 0.1 | D26: =IF($C$6="","",INDEX(マスタ!$B$24:$G$32,MATCH($B26,マスタ!$A$24:$A$32,0),MATCH($C$6,マスタ!$A$3:$A$8,0))) -> 部門責任者と協働環境を整える | E26: 部門責任者・本体経理と協働できる環境を整える | F26: 関係部門の責任者と月一回の対話の場を設ける | G26: 関係部門との調整事項が期日内に合意されている
A27: ファームバリュー | B27: ファームビルディング | C27: =IF($C$6="","",INDEX(マスタ!$B$12:$G$20,MATCH($B27,マスタ!$A$12:$A$20,0),MATCH($C$6,マスタ!$A$3:$A$8,0))) -> 0.15 | D27: =IF($C$6="","",INDEX(マスタ!$B$24:$G$32,MATCH($B27,マスタ!$A$24:$A$32,0),MATCH($C$6,マスタ!$A$3:$A$8,0))) -> チームの品質・法令順守に責任を持つ | E27: チームの業務品質と法令順守に責任を持ち、ナレッジ化を進める | F27: 業務手順書を年2本作り、チームに共有する | G27: 作った手順書がメンバーの業務で使われている
B28: 経営価値創出力 | C28: =IF($C$6="","",INDEX(マスタ!$B$12:$G$20,MATCH($B28,マスタ!$A$12:$A$20,0),MATCH($C$6,マスタ!$A$3:$A$8,0))) -> 0.1 | D28: =IF($C$6="","",INDEX(マスタ!$B$24:$G$32,MATCH($B28,マスタ!$A$24:$A$32,0),MATCH($C$6,マスタ!$A$3:$A$8,0))) -> 経営資料の品質・KPI整合を管理する | E28: 経営資料の品質管理、定型プロセスの整備、KPIの整合確認を自律的に行う | F28: 月次の経営資料の作成手順とチェックリストを整備する | G28: 経営資料が上長の修正なしで経営会議に提出されている
B29: 合計 | C29: =SUM(C20:C28) -> 1 | D29: =IF($C$6="","",IF(ROUND(C29,4)=1,"","ウェイト合計が100%になっていません"))
B30: 専門領域の育成目標 （L1〜L3は必須） | D30: =IF(OR($C$6="",$C$9=""),"","現レベル："&INDEX(マスタ!$C$36:$H$41,MATCH($C$9,マスタ!$A$36:$A$41,0),MATCH($C$6,マスタ!$A$3:$A$8,0))&CHAR(10)&"次のレベル："&INDEX(マスタ!$C$36:$H$41,MATCH($C$9,マスタ!$A$36:$A$41,0),MIN(MATCH($C$6,マスタ!$A$3:$A$8,0)+1,6))) -> 現レベル：MBR運営・予実管理の統括 次のレベル：中期計画・KPI・会議体の設計 | E30: （L4以上は任意）L5の水準である「中期計画・KPI・会議体の設計」に一部取り組む | F30: FY28予算策定でKPI体系の見直し案を作る | G30: 見直し案が上長のレビューを経て経営会議に付議されている
B31: その他（個人目標など） | D31: 資格取得・業務知識など（任意）
A33: ③ コンピテンシー中長期目標（3年後の目安） ※サマリーは必須。目指すレベルでの3年後の姿を書く
B34: 目指すレベル | C34: L5 | D34: =IF($C$34="","",INDEX(マスタ!$B$3:$B$8,MATCH($C$34,マスタ!$A$3:$A$8,0))&"（INTS："&INDEX(マスタ!$F$3:$F$8,MATCH($C$34,マスタ!$A$3:$A$8,0))&"）／"&INDEX(マスタ!$D$3:$D$8,MATCH($C$34,マスタ!$A$3:$A$8,0))) -> アソシエイトディレクター／デピュティディレクター（INTS：Manager〜Senior Manager）／部長補佐・副部長
B35: サマリー（必須） | C35: 3年後はL5 アソシエイトディレクター（INTS：Manager〜Senior Manager）として、バックオフィス全領域の計画・管理の仕組みを設計し、中期計画・KPI・会議体の設計を主導している。
A36: 提供価値 | B36: 評価観点 | D36: 目指すレベルの期待水準（参考） | E36: 3年後の姿
A37: クライアントバリュー | B37: 問題解決能力 | D37: =IF($C$34="","",INDEX(マスタ!$B$24:$G$32,MATCH($B37,マスタ!$A$24:$A$32,0),MATCH($C$34,マスタ!$A$3:$A$8,0))) -> 部門横断の課題の打ち手を設計する | E37: 部門横断の課題について打ち手を設計している
B38: タスク管理・マネジメント力 | D38: =IF($C$34="","",INDEX(マスタ!$B$24:$G$32,MATCH($B38,マスタ!$A$24:$A$32,0),MATCH($C$34,マスタ!$A$3:$A$8,0))) -> 全体のリソース配分を最適化する | E38: Corp Planning全体のリソース配分を最適化している
B39: 口頭コミュニケーション | D39: =IF($C$34="","",INDEX(マスタ!$B$24:$G$32,MATCH($B39,マスタ!$A$24:$A$32,0),MATCH($C$34,マスタ!$A$3:$A$8,0))) -> 対立テーマでも合意形成を主導する | E39: 対立するテーマでも合意形成を主導している
B40: 文書コミュニケーション | D40: =IF($C$34="","",INDEX(マスタ!$B$24:$G$32,MATCH($B40,マスタ!$A$24:$A$32,0),MATCH($C$34,マスタ!$A$3:$A$8,0))) -> 経営向けの方針書・制度案を作成する | E40: 経営向けの方針書・制度案を作成している
B41: 専門性 | D41: =IF($C$34="","",INDEX(マスタ!$B$24:$G$32,MATCH($B41,マスタ!$A$24:$A$32,0),MATCH($C$34,マスタ!$A$3:$A$8,0))) -> 複数領域に精通し制度を設計する | E41: 経営企画と経理・財務に精通し、計画・管理の制度を設計している
A42: ピープルバリュー | B42: 機能人材の確保・育成貢献 | D42: =IF($C$34="","",INDEX(マスタ!$B$24:$G$32,MATCH($B42,マスタ!$A$24:$A$32,0),MATCH($C$34,マスタ!$A$3:$A$8,0))) -> 人材要件の定義と採用・育成計画を作る | E42: Corp Planningの人材要件を定義し、採用・育成計画を作っている
B43: 関係構築・連携 | D43: =IF($C$34="","",INDEX(マスタ!$B$24:$G$32,MATCH($B43,マスタ!$A$24:$A$32,0),MATCH($C$34,マスタ!$A$3:$A$8,0))) -> 本体・ICBPとの連携体制を構築する | E43: 本体・ICBPとの連携体制を構築している
...

Sheet マスタ
A1: マスタ（目標設定シートのプルダウン・自動表示の参照元。編集はCorp Planningのみ）
A2: レベル | B2: タイトル（本体） | C2: 英語表記 | D2: 本体の職位 | E2: 本体の事務職バンド | F2: INTS等級（処遇・評価） | G2: マネジメントスパン（担当領域） | H2: 指導・管理する人数 | I2: KPI目標 | J2: コンピテンシー評価の比率
A3: L1 | B3: スタッフ／サブチーフ | C3: Staff / Sub Chief | D3: 社員・副主任 | E3: A01〜A03 | F3: Associate | G3: 1領域の定型業務（指示された範囲） | H3: なし | I3: 対象外 | J3: 1
A4: L2 | B4: チーフ | C4: Chief | D4: 主任 | E4: A04〜A05 | F4: Consultant | G4: 1領域の業務一式を自立運用＋他領域の定型業務を補助 | H4: なし（新メンバーのOJTを補助） | I4: 対象外 | J4: 1
A5: L3 | B5: アシスタントマネジャー／デピュティマネジャー | C5: Assistant Manager / Deputy Manager | D5: 課長補佐・課長代理 | E5: A06〜A08 | F5: Senior Consultant | G5: 1領域のリード＋隣接1〜2領域の実務 | H5: L1〜L2を1〜2名指導 | I5: 対象外 | J5: 1
A6: L4 | B6: マネジャー | C6: Manager | D6: 課長 | E6: A09 | F6: Manager | G6: 2〜3領域の統括 | H6: 1チーム（2〜4名） | I6: 非財務KPI（評価全体の30%） | J6: 0.7
A7: L5 | B7: アソシエイトディレクター／デピュティディレクター | C7: Associate Director / Deputy Director | D7: 部長補佐・副部長 | E7: A10〜A14 | F7: Manager〜Senior Manager | G7: バックオフィス全領域の制度・仕組みの設計（複数チーム横断） | H7: 複数チーム（5〜10名）＋本体・外部ベンダー | I7: 非財務KPI（評価全体の30%） | J7: 0.7
A8: L6 | B8: ディレクター | C8: Director | D8: 本部長 | E8: A15〜A20 | F8: Director | G8: Corp Planning全機能＋経営アジェンダ | H8: 機能全体（本体・ICBP連携含む） | I8: 非財務KPI（評価全体の30%） | J8: 0.7
A9: 出所：CorpPlanning_タイトル別コンピテンシー定義_ドラフト_v02（レベル体系）、INTS_HRキャリアパス設計_v031（08_INTS_HRタイトル案）。KPI目標はL4以上の非財務KPIのみ（Corp Planningでは財務KPIは設定しない）。比率はコンピテンシー70%・非財務KPI 30%（定義書 Ver.0.14.3のM・SMの比率をL4〜L6に適用）。
A11: 評価観点 | B11: L1 | C11: L2 | D11: L3 | E11: L4 | F11: L5 | G11: L6 | H11: 提供価値
A12: 問題解決能力 | B12: 0.2 | C12: 0.2 | D12: 0.2 | E12: 0.15 | F12: 0.15 | G12: 0.1 | H12: クライアントバリュー
A13: タスク管理・マネジメント力 | B13: 0.2 | C13: 0.2 | D13: 0.2 | E13: 0.15 | F13: 0.15 | G13: 0.1 | H13: クライアントバリュー
A14: 口頭コミュニケーション | B14: 0.1 | C14: 0.1 | D14: 0.1 | E14: 0.08 | F14: 0.08 | G14: 0.05 | H14: クライアントバリュー
A15: 文書コミュニケーション | B15: 0.1 | C15: 0.1 | D15: 0.1 | E15: 0.07 | F15: 0.07 | G15: 0.05 | H15: クライアントバリュー
A16: 専門性 | B16: 0 | C16: 0 | D16: 0 | E16: 0.1 | F16: 0.1 | G16: 0.15 | H16: クライアントバリュー
A17: 機能人材の確保・育成貢献 | B17: 0.1 | C17: 0.1 | D17: 0.1 | E17: 0.1 | F17: 0.1 | G17: 0.1 | H17: ピープルバリュー
A18: 関係構築・連携 | B18: 0.1 | C18: 0.1 | D18: 0.1 | E18: 0.1 | F18: 0.1 | G18: 0.1 | H18: ピープルバリュー
A19: ファームビルディング | B19: 0.1 | C19: 0.1 | D19: 0.1 | E19: 0.15 | F19: 0.15 | G19: 0.15 | H19: ファームバリュー
A20: 経営価値創出力 | B20: 0.1 | C20: 0.1 | D20: 0.1 | E20: 0.1 | F20: 0.1 | G20: 0.2 | H20: ファームバリュー
A21: 合計 | B21: =SUM(B12:B20) -> 1 | C21: =SUM(C12:C20) -> 1 | D21: =SUM(D12:D20) -> 1 | E21: =SUM(E12:E20) -> 1 | F21: =SUM(F12:F20) -> 1 | G21: =SUM(G12:G20) -> 1
A22: 出所：CorpPlanning_タイトル別コンピテンシー定義_ドラフト_v02「レベル別の評価ウェイト」。L1〜L3は現行Junior評価シートのウェイトに統一。
A23: 評価観点 | B23: L1 スタッフ／サブチーフ | C23: L2 チーフ | D23: L3 アシスタントマネジャー／デピュティマネジャー | E23: L4 マネジャー | F23: L5 アソシエイトディレクター／デピュティディレクター | G23: L6 ディレクター
A24: 問題解決能力 | B24: 上長の支援で課題を整理する | C24: 自ら仮説を立てて構造化する | D24: 担当領域の課題を自律的に分析する | E24: 複数領域の論点設定・分析をリードする | F24: 部門横断の課題の打ち手を設計する | G24: 経営アジェンダの論点設定・提言を行う
A25: タスク管理・マネジメント力 | B25: 支援を受け期日・品質を守る | C25: 逆算で計画し進捗を自発的に共有する | D25: 担当領域の計画と後輩の進捗を管理する | E25: 複数領域の計画・予算・品質を管理する | F25: 全体のリソース配分を最適化する | G25: 経営計画と整合した予算・体制を決定する
A26: 口頭コミュニケーション | B26: 報・連・相を確実に行う | C26: 結論から簡潔に伝える | D26: 多人数の会議をファシリテートする | E26: 事業部門・本体と合意形成する | F26: 対立テーマでも合意形成を主導する | G26: 経営会議で意思決定を主導する
A27: 文書コミュニケーション | B27: 指示どおり正確に作成する | C27: 要点を先に示す簡潔な文書を作る | D27: 意思決定に使える規程・資料を作る | E27: チームの成果物の品質に責任を持つ | F27: 経営向けの方針書・制度案を作成する | G27: 全社・グループへ方針を発信する
A28: 専門性 | B28: －（育成目標で管理） | C28: －（育成目標で管理） | D28: －（育成目標で管理） | E28: 主担当領域で市場水準の専門性を持つ | F28: 複数領域に精通し制度を設計する | G28: バックオフィス全般で経営に提言する
A29: 機能人材の確保・育成貢献 | B29: フィードバックを受け改善する | C29: 自ら成長目標を設定し学ぶ | D29: L1〜L2のOJT・業務指導を行う | E29: メンバーの育成計画・キャリア支援を行う | F29: 人材要件の定義と採用・育成計画を作る | G29: Corp Planningの人材方針を策定する
A30: 関係構築・連携 | B30: 指示の範囲で協力する | C30: 本体の担当者と自ら連携する | D30: 担当領域の窓口として調整する | E30: 部門責任者と協働環境を整える | F30: 本体・ICBPとの連携体制を構築する | G30: 経営層・グループと信頼関係を構築する
A31: ファームビルディング | B31: ルールを理解し実践する | C31: 運用する側として改善を提案する | D31: 担当領域の改善・ナレッジ化を進める | E31: チームの品質・法令順守に責任を持つ | F31: 品質・リスク管理の仕組みを整備する | G31: カルチャー・リスク文化を醸成する
A32: 経営価値創出力 | B32: 精度・期限を守り完遂する | C32: 上長の確認が不要な精度で作成する | D32: レポート品質とデータ整合を担保する | E32: 経営資料の品質・KPI整合を管理する | F32: KPI体系・計画プロセスを設計する | G32: 経営の意思決定速度に直接貢献する
A33: 出所：同ドラフト v02「コンピテンシー定義（期待水準の要約）」。全文はExcelの「02_コンピテンシー定義」を参照。
A35: 専門領域 | B35: タイトルに付ける機能名（仮） | C35: L1 | D35: L2 | E35: L3 | F35: L4 | G35: L5 | H35: L6
A36: 人事・労務 | B36: HR | C36: 入退社・勤怠・社保の手続 | D36: 労務運用・評価の事務局 | E36: 運用設計・規程改定の起案 | F36: 評価・採用・育成の統括 | G36: 要員計画・人事制度の設計 | H36: 人事戦略・報酬原資の決定
A37: 総務 | B37: GA | C37: 備品・施設の依頼を処理 | D37: 総務運用・社内イベント運営 | E37: 総務プロセス設計・ベンダー管理 | F37: 総務・規程・監査対応の統括 | G37: BCP・リスク管理方針の策定 | H37: リスク・コンプラ統制の責任者
A38: 経理・財務 | B38: FIN | C38: 経費精算・請求書のチェック | D38: 計数集計・本体経理との照合 | E38: 月次決算・予実分析のリード | F38: 予算・予実・採算管理の統括 | G38: 中期財務・人件費計画の策定 | H38: 財務戦略・投資判断
A39: 広報・ブランディング | B39: PR | C39: 社内報・SNS・HPの更新 | D39: 社内・採用広報の企画作成 | E39: 広報計画・Corporate Site管理 | F39: 採用ブランディング・発信の統括 | G39: ブランド戦略の策定 | H39: ブランド・評判の責任者
A40: IT・情報セキュリティ | B40: IT | C40: アカウント・PC手配・一次対応 | D40: SaaS・AIツールの運用管理 | E40: AI活用の企画・セキュリティ運用 | F40: 社内IT・セキュリティ・DXの統括 | G40: IT・DX戦略とセキュリティ方針 | H40: ITガバナンスの責任者
A41: 経営企画・業績管理 | B41: CP | C41: 経営情報の収集・入力 | D41: MBRの集計・資料作成 | E41: KPI分析・会議資料の品質担保 | F41: MBR運営・予実管理の統括 | G41: 中期計画・KPI・会議体の設計 | H41: 経営計画・経営会議を主導
A42: 出所：同ドラフト v02「専門領域スキル」。機能名はHR・FIN以外は仮置き（GA・PR・IT・CP）。
...
