Workbook

Sheet FY26アーカイブ
G1: KPI該当有無の整理 | J1: FY25対象 | K1: FY26対象 | M1: PracticeリーダーKPI | P1: MD・D 個人KPI | S1: PracticeリーダーKPI | V1: MD・D 個人KPI | Y1: Accountリーダー KPI | AB1: 非財務KPI | AG1: Weight
G2: KPI該当有無の整理 | J2: FY25対象 | K2: FY26対象 | M2: PracticeリーダーKPI | P2: MD・D 個人KPI | S2: PracticeリーダーKPI | V2: MD・D 個人KPI | Y2: Accountリーダー KPI | AB2: 非財務KPI | AG2: Weight
J3: 対象有無 | K3: 対象有無 | L3: 評価期間 | M3: グロス売上 | P3: Sales Contribution | S3: グロス売上 | T3: グロス稼働率 | U3: グロスDiscount率 | V3: Sales Contribution | W3: Managed Revenue | X3: 有償稼働率 | AG3: PracticeリーダーKPI | AI3: Account リーダー | AL3: MD・D個人 | AO3: 非財務 | AT3: 合計
B4: 氏名 | C4: 入社年月日 | D4: Title | E4: Organization | F4: 所属Pracice | G4: Practiceリーダー KPI | H4: Accountリーダー KPI | I4: MDD KPI | M4: 入社1年目 | N4: 入社2年目 | O4: 入社3年目 | P4: 入社1年目 | Q4: 入社2年目 | R4: 入社3年目 | S4: FY26 | T4: FY26 | U4: FY26 | V4: FY26 | W4: FY26 | X4: FY26 | Y4: アカウント名 | Z4: アカウント受注額 | AA4: アカウント売上高 | AB4: 採用 | AC4: 顧客リレーション | AD4: リード創出 | AE4: 教育／育成 | AF4: Thought Leadership | AG4: グロス売上 | AH4: 有償稼働率(組織トータル) | AI4: グロスDiscount率 | AJ4: アカウント受注額 | AK4: アカウント売上高 | AL4: Sales Contribution | AM4: Managed Revenue | AN4: 有償稼働率(個人) | AO4: 採用 | AP4: セールス前工程 | AQ4: 教育／育成 | AR4: Thought Leadership | AS4: AI活用
B5: 渋谷 賢吾 | C5: 45717 | D5: MD | E5: Industry | F5: Telecom | G5: ○ | H5: ○ | I5: ○ | J5: Yes | K5: Yes | L5: 12 | M5: 150 | N5: 400 | O5: 1000 | P5: 200 | Q5: 400 | R5: 600 | S5: 254 | T5: 0.9 | U5: 0.07 | V5: 283 | W5: 254 | X5: 0.4 | Y5: KDDI | Z5: 433 | AA5: 433 | AB5: ・通信業界の戦略コンサルタント経験者を年間7名以上面談し、うち3名以上の内定承諾に貢献 | AC5: ・既存クライアントにおいて、部門責任者またはCXOレベルとの四半期ごとの戦略対話を主導 | AD5: ・既存顧客及び関連会社へのアプローチをリードし、うち2社で大型案件を受注 | AE5: ・通信業界の事業戦略立案手法に関する社内トレーニングを年3回開催 | AF5: ・Future of Telecomシリーズに類する通信業界の未来デザインに関するホワイトペーパーを年1本発信 | AG5: 0.1 | AH5: 0.1 | AI5: 0.1 | AJ5: 0.1 | AK5: 0.1 | AL5: 0.083 | AM5: 0.083 | AN5: 0.083 | AO5: 0.05 | AP5: 0.05 | AQ5: 0.05 | AR5: 0.05 | AS5: 0.05 | AT5: 1
AB6: ・通信業界向けキャリアセミナーやネットワーキングイベントに3回以上参画 | AC6: ・法人DX、AI、5G/6G動向、スマートシティ、グローバル事業展開などに関する情報提供セッションを年6回以上実施 | AD6: ・Future of Telecomシリーズ等のThought Leadershipコンテンツを活用した提案活動を実施 | AE6: ・Practice内メンバーに対する定期的なメンタリングとフィードバックを実施 | AF6: ・業界カンファレンスまたはウェビナーへの登壇を年2回以上実施し、Practice Leaderとしてのプレゼンスを強化
B7: 東條 貴志 | C7: 45474 | D7: MD | E7: Industry | F7: Technology | H7: ○ | I7: ○ | J7: Yes | K7: Yes | L7: 12 | M7: N/A | N7: N/A | O7: N/A | P7: 200 | Q7: 200 | R7: 0 | S7: N/A | T7: N/A | U7: N/A | V7: 183 | W7: 183 | X7: 0.4 | Y7: CTC | Z7: 1619 | AA7: 1619 | AB7: (小澤さん作成中) | AC7: (小澤さん作成中) | AD7: (小澤さん作成中) | AE7: (小澤さん作成中) | AF7: (小澤さん作成中) | AG7: N/A | AH7: N/A | AI7: N/A | AJ7: 0.125 | AK7: 0.125 | AL7: 0.167 | AM7: 0.167 | AN7: 0.167 | AO7: 0.05 | AP7: 0.05 | AQ7: 0.05 | AR7: 0.05 | AS7: 0.05 | AT7: 1
F8: Innovation (2027/08-) | Y8: （1/1より加藤さんに移行）
B9: 加藤 節雄 | C9: 45870 | D9: MD | E9: Industry | F9: Technology | G9: ○ | H9: ○ | I9: ○ | J9: No | K9: Yes | L9: 12 | M9: 500 | N9: 1300 | O9: 2500 | P9: 270 | Q9: 650 | R9: 1400 | S9: 500 | T9: 0.9 | U9: 0.07 | V9: 270 | W9: 500 | X9: 0.4 | Y9: NEC | Z9: 779 | AA9: 779 | AB9: ・テクノロジー領域のコンサルタント経験者を年間7名以上面談し、うち3名以上の内定承諾に貢献 | AC9: ・新規クライアント含む3社において、CIOまたはIT戦略責任者との四半期ごとの戦略対話を主導 | AD9: ・ERP/DXニーズを持つ新規クライアント4社へのアプローチをリードし、うち2社でパイロット案件を受注 | AE9: ・ERP導入手法または生成AI活用に関する社内トレーニングを年3回開催 | AF9: ・DXまたはERP導入に関するホワイトペーパーを年2本発信 | AG9: 0.1 | AH9: 0.1 | AI9: 0.1 | AJ9: 0.1 | AK9: 0.1 | AL9: 0.083 | AM9: 0.083 | AN9: 0.083 | AO9: 0.05 | AP9: 0.05 | AQ9: 0.05 | AR9: 0.05 | AS9: 0.05 | AT9: 1
AB10: ・ERP/DX関連のセミナーまたは採用イベントに2回以上参画 | AC10: ・ERP導入や生成AI活用に関する情報提供セッションを年6回以上実施 | AD10: ・生成AI活用事例やシステム統合実績を活用した提案活動を実施 | AE10: ・大規模PMOプロジェクトにおいて3名以上のメンバーへの実務指導を実施 | AF10: ・ITカンファレンスまたは経営層向けDXフォーラムへの登壇を年1回以上実施
B11: 福島 毅 | C11: 45597 | D11: D | E11: Industry | F11: Technology | I11: ○ | J11: Yes | K11: Yes | L11: 12 | M11: N/A | N11: N/A | O11: N/A | P11: 200 | Q11: 400 | R11: 600 | S11: N/A | T11: N/A | U11: N/A | V11: 350 | W11: 350 | X11: 0.5 | Y11: N/A | Z11: N/A | AA11: N/A | AB11: ・DX/業務改革領域の経験者（PMO、BPRスペシャリスト等）を年間5名以上面談し、うち2名以上の内定承諾に貢献 | AC11: ・ターゲットアカウントにおいて、CIOまたはCDOレベルとの定期的な関係構築を推進 | AD11: ・大規模プログラム推進や業務改革ニーズを持つ新規クライアント3社へアプローチし、うち1社でパイロット案件を受注 | AE11: ・大規模プログラム推進手法に関する社内トレーニングを年1回開催し、PM・PMOスキルの底上げを図る | AF11: ・DX推進やプログラムマネジメントに関するホワイトペーパーを年1本発信 | AG11: N/A | AH11: N/A | AI11: N/A | AJ11: N/A | AK11: N/A | AL11: 0.25 | AM11: 0.25 | AN11: 0.25 | AO11: 0.05 | AP11: 0.05 | AQ11: 0.05 | AR11: 0.05 | AS11: 0.05 | AT11: 1
AC12: ・DX推進課題に関する戦略セッションを各社四半期ごとに実施し、継続的な信頼関係を強化 | AD12: ・DX事例やベストプラクティスを活用した提案活動を月次で実施 | AE12: ・プロジェクトにおいて3名以上のメンバーへのOJT指導を実施し、プログラムマネジメント能力を育成 | AF12: ・業界カンファレンスまたはウェビナーへの登壇を年1回以上実施
B13: 藤川 真一 | C13: 46054 | D13: MD | E13: Industry | F13: Technology | H13: ○ | I13: ○ | J13: No | K13: Yes | L13: 6 | M13: N/A | N13: N/A | O13: N/A | P13: 200 | Q13: 400 | R13: 600 | S13: N/A | T13: N/A | U13: N/A | V13: 100 | W13: 100 | X13: 0.4 | Y13: パナソニック | Z13: 100 | AA13: 100 | AB13: (作成予定) | AC13: (作成予定) | AD13: (作成予定) | AE13: (作成予定) | AF13: (作成予定) | AG13: N/A | AH13: N/A | AI13: N/A | AJ13: 0.125 | AK13: 0.125 | AL13: 0.167 | AM13: 0.167 | AN13: 0.167 | AO13: 0.05 | AP13: 0.05 | AQ13: 0.05 | AR13: 0.05 | AS13: 0.05 | AT13: 1
B14: 藤澤 賢成 | C14: 45748 | D14: D | E14: Industry | F14: Finanace Service | H14: ○ | I14: ○ | J14: Yes | K14: Yes | L14: 12 | M14: N/A | N14: N/A | O14: N/A | P14: 200 | Q14: 400 | R14: 600 | S14: N/A | T14: N/A | U14: N/A | V14: 267 | W14: 267 | X14: 0.5 | Y14: 野村HD・MUFG | Z14: 90 | AA14: 90 | AB14: ・金融領域の専門人材を年間5名以上面談し、うち2名以上の内定承諾に貢献 | AC14: ・ターゲットアカウントにおいて、CROまたはCCOレベルとの四半期ごとの戦略ディスカッションを主導 | AD14: ・Basel規制対応やAML/CFT高度化ニーズを持つ新規金融機関2社へのアプローチをリードし、1件以上のパイロット案件を受注 | AE14: ・金融規制・リスク管理に関する社内勉強会を年1回以上開催し、ジュニアコンサルタントの専門性向上を支援 | AF14: ・Basel規制やAML高度化に関するホワイトペーパーまたは業界誌への寄稿を年1本発信（上期1本、下期1本） | AG14: N/A | AH14: N/A | AI14: N/A | AJ14: 0.125 | AK14: 0.125 | AL14: 0.167 | AM14: 0.167 | AN14: 0.167 | AO14: 0.05 | AP14: 0.05 | AQ14: 0.05 | AR14: 0.05 | AS14: 0.05 | AT14: 1
AC15: ・金融規制動向やリスク管理高度化に関する情報提供セッションを年3回以上実施 | AD15: ・金融当局動向レポートを活用した提案機会創出を四半期ごとに実施 | AE15: ・プロジェクトにおいて2名以上のメンバーへのOJT・メンタリングを実施し、金融規制対応スキルを伝達 | AF15: ・金融規制セミナーへの登壇を年1回以上実施し、ファームの専門性を対外発信
B16: 深谷 匡隆 | C16: 45870 | D16: MD | E16: Industry | F16: Consumer＆Retail(2025/11末まで) | G16: ○ | H16: ○ | I16: ○ | J16: No | K16: Yes | L16: 12 | M16: 400 | N16: 600 | O16: 1000 | P16: 200 | Q16: 400 | R16: 600 | S16: 400 | T16: 0.9 | U16: 0.07 | V16: 200 | W16: 400 | X16: 0.4 | Y16: ANA・JAL | Z16: 250 | AA16: 250 | AB16: ・運輸業界に専門性のある戦略コンサルタント経験者を年間7名以上面談し、うち3名以上の内定承諾に貢献 | AC16: ・既存クライアント3社において、経営トップまたは事業責任者レベルとの四半期ごとの戦略ディスカッションを主導 | AD16: ・新規クライアント5社へのアプローチをリードし、うち3社でパイロット案件を受注 | AE16: ・運輸業界の事業戦略立案手法に関する社内トレーニングを年3回開催 | AF16: ・製造業または小売業の成長戦略に関するホワイトペーパーを年1本発信 | AG16: 0.1 | AH16: 0.1 | AI16: 0.1 | AJ16: 0.1 | AK16: 0.1 | AL16: 0.083 | AM16: 0.083 | AN16: 0.083 | AO16: 0.05 | AP16: 0.05 | AQ16: 0.05 | AR16: 0.05 | AS16: 0.05 | AT16: 1
F17: Transportation(2025/12～) | AB17: ・経営層向けネットワーキングイベントや採用セッションに2回以上参画 | AC17: ・M&A戦略、新規事業立案、DX推進に関する定期的な情報交換セッションを年6回以上実施 | AD17: ・Thought Leadershipコンテンツを活用した提案活動を実施 | AE17: ・Practice内メンバーに対する定期的なメンタリングとフィードバックを実施 | AF17: ・経営層向けフォーラムまたは業界カンファレンスへの登壇を年1回以上実施
B18: 中尾 亮 | C18: 45992 | D18: D | E18: Industry | F18: Consumer＆Retail | G18: ○ | H18: ○ | I18: ○ | J18: No | K18: Yes | L18: 8 | M18: 330 | N18: 660 | O18: 1126 | P18: 330 | Q18: 462 | R18: 704 | S18: 220 | T18: 0.9 | U18: 0.07 | V18: 133 | W18: 220 | X18: 0.5 | Y18: JTB | Z18: 100 | AA18: 100 | AB18: ・流通小売・消費財業界の戦略コンサルタント経験者を年間5名以上面談し、うち2名以上の内定承諾に貢献 | AC18: ・ターゲットアカウントにおいて、経営企画責任者レベルとの四半期ごとの戦略ディスカッションを実施 | AD18: ・ターゲットアカウントへのアプローチをリードし、パイロット案件を受注 | AE18: ・成長戦略立案手法に関する社内ワークショップを年2回開催 | AF18: ・流通小売業界の成長戦略またはサステナビリティ戦略に関するホワイトペーパーを年1本発信 | AG18: 0.083 | AH18: 0.083 | AI18: 0.083 | AJ18: 0.125 | AK18: 0.125 | AL18: 0.083 | AM18: 0.083 | AN18: 0.083 | AO18: 0.05 | AP18: 0.05 | AQ18: 0.05 | AR18: 0.05 | AS18: 0.05 | AT18: 1
AC19: ・サステナビリティ戦略やサプライチェーン改革に関する情報提供セッションを年3回以上実施 | AD19: ・業界トレンド分析やベンチマーク情報を活用した提案活動を四半期ごとに実施 | AE19: ・プロジェクトにおいて3名以上のジュニアコンサルタントへのOJT指導を実施し、戦略思考力を育成 | AF19: ・業界セミナーまたはフォーラムへの登壇を年1回以上実施
B20: 髙橋 敦 | C20: 45931 | D20: D | E20: Industry | F20: Auto→Construction | G20: ○ | H20: ○ | I20: ○ | J20: No | K20: Yes | L20: 10 | M20: 50 | N20: 150 | O20: 250 | P20: 150 | Q20: 300 | R20: 400 | S20: 42 | T20: 0.9 | U20: 0.07 | V20: 125 | W20: 125 | X20: 0.5 | Y20: 日産 | Z20: 300 | AA20: 300 | AB20: ・建設・不動産業界のコンサルタント経験者を年間5名以上面談し、うち2名以上の内定承諾に貢献 | AC20: ・既存建設・不動産クライアント2社において、事業責任者レベルとの四半期ごとの戦略ディスカッションを実施 | AD20: ・新規建設・不動産企業または自治体3社へのアプローチをリードし、うち1社でパイロット案件を受注 | AE20: ・建設業界の戦略策定手法に関する社内勉強会を年2回開催 | AF20: ・スマートシティまたは建設業界の未来戦略に関するホワイトペーパーを年1本発信 | AG20: 0.083 | AH20: 0.083 | AI20: 0.083 | AJ20: 0.125 | AK20: 0.125 | AL20: 0.083 | AM20: 0.083 | AN20: 0.083 | AO20: 0.05 | AP20: 0.05 | AQ20: 0.05 | AR20: 0.05 | AS20: 0.05 | AT20: 1
AC21: ・スマートシティ戦略やモビリティサービスに関する情報提供セッションを年4回以上開催 | AD21: ・スマートシティ構想や未来洞察レポートを活用した提案活動を実施 | AE21: ・プロジェクトにおいて2名以上のメンバーへのOJT指導を実施 | AF21: ・スマートシティフォーラムまたは建設業界セミナーへの登壇を年1回以上実施
B22: 高橋 新 | C22: 46023 | D22: D | E22: Industry | F22: Auto | G22: ○ | H22: ○ | I22: ○ | J22: No | K22: Yes | L22: 7 | M22: 300 | N22: 600 | O22: 850 | P22: 200 | Q22: 400 | R22: 600 | S22: 175 | T22: 0.9 | U22: 0.07 | V22: 117 | W22: 175 | X22: 0.5 | Y22: ホンダ | Z22: 1044 | AA22: 1044 | AB22: ・金融領域の専門人材を年間5名以上面談し、うち2名以上の内定承諾に貢献 | AC22: ・ターゲットアカウントにおいて、CFOまたは経営企画責任者との四半期ごとの戦略対話を実施 | AD22: ・新規金融機関または製造業3社へのアプローチをリードし、うち1社でM&A関連案件を受注 | AE22: ・M&A/PMI手法に関する社内勉強会を年2回開催 | AF22: ・M&Aまたは事業再編に関する論考を年1本発信 | AG22: 0.083 | AH22: 0.083 | AI22: 0.083 | AJ22: 0.125 | AK22: 0.125 | AL22: 0.083 | AM22: 0.083 | AN22: 0.083 | AO22: 0.05 | AP22: 0.05 | AQ22: 0.05 | AR22: 0.05 | AS22: 0.05 | AT22: 1
AC23: ・M&A戦略やグローバル経営に関する情報提供セッションを年4回以上開催 | AD23: ・事業再編やカーブアウト事例を活用した提案活動を四半期ごとに実施 | AE23: ・プロジェクトにおいて2名以上のメンバーへのOJT指導を実施 | AF23: ・M&Aフォーラムまたは金融業界セミナーへの登壇を年1回以上実施
B24: 石川 利一 | C24: 45931 | D24: D | E24: Industry | F24: Public | G24: ○ | I24: ○ | J24: No | K24: Yes | L24: 10 | M24: 500 | N24: 1300 | O24: 2500 | P24: 275 | Q24: 700 | R24: 1500 | S24: 417 | T24: 0.9 | U24: 0.07 | V24: 229 | W24: 417 | X24: 0.5 | Y24: 官公庁 | Z24: 100 | AA24: 100 | AB24: ・アバナードメンバーのスムーズな転籍プログラムの実行 | AC24: ・官公庁または公共機関の既存クライアント2機関において、部局長レベルとの定期的なリレーション活動を実施 | AD24: ・新規官公庁または自治体2機関へのアプローチをリードし、1件以上のプロジェクトを受注 | AE24: ・官公庁ビジネスの特性や年金・社会保障制度に関する社内勉強会を年2回開催 | AF24: ・行政DXまたは社会保障政策に関する論考を年1本発信 | AG24: 0.083 | AH24: 0.083 | AI24: 0.083 | AJ24: 0.125 | AK24: 0.125 | AL24: 0.083 | AM24: 0.083 | AN24: 0.083 | AO24: 0.05 | AP24: 0.05 | AQ24: 0.05 | AR24: 0.05 | AS24: 0.05 | AT24: 1
AC25: ・行政DXや社会保障制度改革に関する情報提供セッションを年3回以上実施 | AD25: ・政策動向レポートや先進事例紹介を活用した提案活動を実施 | AE25: ・公共セクタープロジェクトにおいて2名以上のメンバーへの実務指導を実施 | AF25: ・公共政策フォーラムまたは自治体向けセミナーへの登壇を年1回以上実施
B26: 池田 正昭 | C26: 45778 | D26: MD | E26: Solution | F26: Corporate Finance | G26: ○ | H26: ○ | I26: ○ | J26: Yes | K26: Yes | L26: 12 | M26: 200 | N26: 400 | O26: 500 | P26: 200 | Q26: 400 | R26: 600 | S26: 250 | T26: 0.9 | U26: 0.07 | V26: 250 | W26: 250 | X26: 0.4 | Y26: OSG | Z26: 100 | AA26: 100 | AB26: ・コーポレートファイナンスまたはM&A経験者を年間7名以上面談し、うち3名以上の内定承諾に貢献 | AC26: ・既存クライアント3社において、CFOまたはM&A責任者との四半期ごとの戦略対話を主導 | AD26: ・M&Aまたは事業再編ニーズを持つ新規クライアント4社へのアプローチをリードし、うち2社でパイロット案件を受注 | AE26: ・コーポレートファイナンス手法に関する社内トレーニングを年3回開催 | AF26: ・M&Aまたは事業戦略に関するホワイトペーパーを年2本発信 | AG26: 0.1 | AH26: 0.1 | AI26: 0.1 | AJ26: 0.1 | AK26: 0.1 | AL26: 0.083 | AM26: 0.083 | AN26: 0.083 | AO26: 0.05 | AP26: 0.05 | AQ26: 0.05 | AR26: 0.05 | AS26: 0.05 | AT26: 1
AB27: ・ファイナンス系キャリアセミナーまたはネットワーキングイベントに2回以上参画 | AC27: ・M&A市場動向やバリュエーション手法に関する情報提供セッションを年3回以上実施 | AD27: ・デューデリジェンスやPMI事例を活用した提案活動を四半期ごとに実施 | AE27: ・Practice内メンバー3名以上に対する定期的なメンタリングを実施 | AF27: ・M&Aカンファレンスまたは経営フォーラムへの登壇を年1回以上実施
B28: 北村 史郎 | C28: 46023 | D28: D | E28: Solution | F28: Corporate Finance | I28: ○ | J28: No | K28: Yes | L28: 7 | M28: N/A | N28: N/A | O28: N/A | P28: 200 | Q28: 400 | R28: 600 | S28: N/A | T28: N/A | U28: N/A | V28: 117 | W28: 117 | X28: 0.5 | Y28: N/A | Z28: N/A | AA28: N/A | AB28: (作成予定) | AC28: (作成予定) | AD28: (作成予定) | AE28: (作成予定) | AF28: (作成予定) | AG28: N/A | AH28: N/A | AI28: N/A | AJ28: N/A | AK28: N/A | AL28: 0.25 | AM28: 0.25 | AN28: 0.25 | AO28: 0.05 | AP28: 0.05 | AQ28: 0.05 | AR28: 0.05 | AS28: 0.05 | AT28: 1
B29: 吉田 卓史 | C29: 45931 | D29: MD | E29: Solution | F29: Cyber Securiy | G29: ○ | I29: ○ | J29: No | K29: Yes | L29: 10 | M29: 200 | N29: 600 | O29: 1100 | P29: 200 | Q29: 400 | R29: 600 | S29: 167 | T29: 0.9 | U29: 0.07 | V29: 167 | W29: 167 | X29: 0.4 | Y29: N/A | Z29: N/A | AA29: N/A | AB29: ・サイバーセキュリティ専門人材（CISO、SOC経験者等）を年間7名以上面談し、うち3名以上の内定承諾に貢献 | AC29: ・新規クライアント含む3社において、CISOまたはセキュリティ責任者との四半期ごとの戦略対話を主導 | AD29: ・セキュリティ強化ニーズを持つ新規クライアント4社へのアプローチをリードし、うち2社でパイロット案件を受注 | AE29: ・サイバーセキュリティガバナンスに関する社内トレーニングを年3回開催 | AF29: ・サイバーセキュリティ戦略またはゼロトラストアーキテクチャに関するホワイトペーパーを年2本発信 | AG29: 0.125 | AH29: 0.125 | AI29: 0.125 | AJ29: N/A | AK29: N/A | AL29: 0.125 | AM29: 0.125 | AN29: 0.125 | AO29: 0.05 | AP29: 0.05 | AQ29: 0.05 | AR29: 0.05 | AS29: 0.05 | AT29: 1
AB30: ・セキュリティカンファレンスまたは採用セッションに2回以上参画 | AC30: ・サイバーセキュリティ脅威動向やガバナンス強化に関する情報提供セッションを年6回以上実施 | AD30: ・グローバルセキュリティ体制構築事例やSOC立ち上げ実績を活用した提案活動を実施 | AE30: ・Practice内メンバー3名以上に対する定期的なメンタリングとスキル育成を実施 | AF30: ・セキュリティカンファレンスへの登壇を年2回以上実施し、Practice Leaderとしてのプレゼンスを確立
B31: 玉井 俊行 | C31: 46069 | D31: D | E31: Industry | F31: Public | J31: No | Y31: N/A | Z31: N/A | AA31: N/A | AB31: N/A | AC31: N/A | AD31: N/A | AE31: N/A | AF31: N/A
B32: 高橋 聖 | C32: 46082 | D32: D | E32: Solution | F32: AI＆Data | J32: No | Y32: N/A | Z32: N/A | AA32: N/A | AB32: N/A | AC32: N/A | AD32: N/A | AE32: N/A | AF32: N/A
B33: 上瀬 剛 | C33: 46113 | D33: D | E33: Industry | F33: Public | J33: No | Y33: N/A | Z33: N/A | AA33: N/A | AB33: N/A | AC33: N/A | AD33: N/A | AE33: N/A | AF33: N/A
B34: 齋地 禎昭 | C34: 46113 | D34: D | E34: Industry | F34: Auto | J34: No | Y34: N/A | Z34: N/A | AA34: N/A | AB34: N/A | AC34: N/A | AD34: N/A | AE34: N/A | AF34: N/A
B35: 大塩 大輔 | C35: 46143 | D35: MD | E35: Industry | F35: Public | J35: No | Y35: N/A | Z35: N/A | AA35: N/A | AB35: N/A | AC35: N/A | AD35: N/A | AE35: N/A | AF35: N/A

Sheet 論点・確認事項
B1: FY27 MDD目標設定：論点・確認事項一覧
B3: 対象者 | C3: BP | D3: 論点・確認事項
B4: 高橋 聖 | C4: あり | D4: ・近藤さん退職のためPLとして整理
B5: 高橋 新 | C5: あり | D5: ・FY26シートの300/600/850は髙橋敦さんのAuto分を合算した経緯によるもの ・FY27からはAuto/Constructionが分割済みのため、単体のBP値200/400/600に変更（FY27=317）
B6: 齋地 禎昭 | C6: あり | D6: ・BPに売上数値の記載がない（テンプレートのまま）ため、標準2/4/6億を仮置き（FY27=267） ・本人に数値を確認するか、標準値で確定するか
B7: 髙橋 敦 | C7: あり | D7: ・BPの建設・不動産ユニット（50/150/250）を厳密に適用するとFY27グロス133＜SC275の逆転が発生（BPの個人売上はAuto等の他プラクティス分を含むため） ・グロスを建設ユニット値のままとするか、「他プラクティスへのSC」と整理して別の置き方をするか
B8: 中尾 亮 | C8: あり | D8: -
B9: 池田 正昭 | C9: あり | D9: -
B10: 北村 史郎 | C10: あり | D10: ・BPの4億/6億はユニット売上。本人売上は各年2億のため200/200/200に変更（FY27=200）
B11: 吉田 卓史 | C11: あり | D11: -
B12: 藤澤 賢成 | C12: あり | D12: -
B13: 大塩 大輔 | C13: なし | D13: ・PublicのPLは石川さんであったが大塩さんで整理 ・BPがないため標準2/4/6億で設定（FY27=250）
B14: 石川 利一 | C14: あり | D14: ・FY27は大塩さん（MD）着任によりPL対象外に変更。評価ウェイトもAL＋個人型に変更済み
... B23: （全体）Managed Revenue | C23: - | D23: ・目標設定上はMR＝SCと同額（全員W列=V列）。FY26の目標設定の運用を踏襲 ・評価プロセス説明会(p52)の定義では、MRは「品質責任者が担当するPJの受注額合計」（案件単位で1名に100%付与）であり、実績は案件ごとの品質責任者ベースで算定される ・目標と実績で概念が異なる点に留意
B24: 組織稼働率 | D24: 90％のロジックが不明
B25: Sales Contribution | D25: どのようなロジックでネット売上から配分するか

Sheet FY27目標設定
B2: 氏名 | C2: 入社年月日 | D2: Title | E2: Organization | F2: 所属Pracice | G2: KPI該当有無の整理 | J2: FY26対象 | K2: FY27対象 | M2: PracticeリーダーKPI | P2: MD・D 個人KPI | S2: PracticeリーダーKPI | V2: MD・D 個人KPI | Y2: Accountリーダー KPI | AB2: 非財務KPI | AG2: Weight
M3: グロス売上 | P3: Sales Contribution | S3: グロス売上 | T3: グロス稼働率 | U3: グロスDiscount率 | V3: Sales Contribution | W3: Managed Revenue | X3: 有償稼働率 | AG3: PracticeリーダーKPI | AJ3: Account リーダー | AL3: MD・D個人 | AO3: 非財務 | AT3: 合計
G4: Practiceリーダー KPI | H4: Accountリーダー KPI | I4: MDD KPI | J4: 対象有無 | K4: 対象有無 | L4: 評価期間 | M4: 入社1年目 | N4: 入社2年目 | O4: 入社3年目 | P4: 入社1年目 | Q4: 入社2年目 | R4: 入社3年目 | S4: FY27 | T4: FY27 | U4: FY27 | V4: FY27 | W4: FY27 | X4: FY27 | Y4: アカウント名 | Z4: アカウント受注額 | AA4: アカウント売上高 | AB4: 採用 | AC4: 顧客リレーション | AD4: リード創出 | AE4: 教育／育成 | AF4: Thought Leadership | AG4: グロス売上 | AH4: 有償稼働率(組織トータル) | AI4: グロスDiscount率 | AJ4: アカウント受注額 | AK4: アカウント売上高 | AL4: Sales Contribution | AM4: Managed Revenue | AN4: 有償稼働率(個人) | AO4: 採用 | AP4: セールス前工程 | AQ4: 教育／育成 | AR4: Thought Leadership | AS4: AI活用
B5: 高橋 聖 | C5: 46082 | D5: D | E5: Solution | F5: AI & Data | G5: ○ | H5: - | I5: ○ | J5: No | K5: Yes | L5: 12 | M5: =SUMIFS(月次バックデータ!$H:$H,月次バックデータ!$B:$B,$B5,月次バックデータ!$E:$E,"グロス売上") -> 230 | N5: =SUMIFS(月次バックデータ!$I:$I,月次バックデータ!$B:$B,$B5,月次バックデータ!$E:$E,"グロス売上") -> 600 | O5: =SUMIFS(月次バックデータ!$J:$J,月次バックデータ!$B:$B,$B5,月次バックデータ!$E:$E,"グロス売上") -> 840 | P5: =SUMIFS(月次バックデータ!$H:$H,月次バックデータ!$B:$B,$B5,月次バックデータ!$E:$E,"Sales Contribution") -> 230 | Q5: =SUMIFS(月次バックデータ!$I:$I,月次バックデータ!$B:$B,$B5,月次バックデータ!$E:$E,"Sales Contribution") -> 600 | R5: =SUMIFS(月次バックデータ!$J:$J,月次バックデータ!$B:$B,$B5,月次バックデータ!$E:$E,"Sales Contribution") -> 840 | S5: =ROUND(SUMIFS(月次バックデータ!$M:$M,月次バックデータ!$B:$B,$B5,月次バックデータ!$E:$E,"グロス売上"),0) -> 600 | T5: 0.9 | U5: 0.07 | V5: =ROUND(SUMIFS(月次バックデータ!$M:$M,月次バックデータ!$B:$B,$B5,月次バックデータ!$E:$E,"Sales Contribution"),0) -> 600 | W5: =V5 -> 600 | X5: 0.5 | Y5: - | Z5: - | AA5: - | AB5: (作成予定) | AC5: (作成予定) | AD5: (作成予定) | AE5: (作成予定) | AF5: (作成予定) | AG5: =0.5/3 -> 0.16666667 | AH5: =0.5/3 -> 0.16666667 | AI5: =0.5/3 -> 0.16666667 | AJ5: - | AK5: - | AL5: =0.25/3 -> 0.083333333 | AM5: =0.25/3 -> 0.083333333 | AN5: =0.25/3 -> 0.083333333 | AO5: 0.05 | AP5: 0.05 | AQ5: 0.05 | AR5: 0.05 | AS5: 0.05 | AT5: =SUM(AG5:AS5) -> 1
B6: 高橋 新 | C6: 46023 | D6: D | E6: Industry | F6: Automotive & Mobility Sector | G6: ○ | H6: ○ | I6: ○ | J6: No | K6: Yes | L6: 12 | M6: =SUMIFS(月次バックデータ!$H:$H,月次バックデータ!$B:$B,$B6,月次バックデータ!$E:$E,"グロス売上") -> 200 | N6: =SUMIFS(月次バックデータ!$I:$I,月次バックデータ!$B:$B,$B6,月次バックデータ!$E:$E,"グロス売上") -> 400 | O6: =SUMIFS(月次バックデータ!$J:$J,月次バックデータ!$B:$B,$B6,月次バックデータ!$E:$E,"グロス売上") -> 600 | P6: =SUMIFS(月次バックデータ!$H:$H,月次バックデータ!$B:$B,$B6,月次バックデータ!$E:$E,"Sales Contribution") -> 200 | Q6: =SUMIFS(月次バックデータ!$I:$I,月次バックデータ!$B:$B,$B6,月次バックデータ!$E:$E,"Sales Contribution") -> 400 | R6: =SUMIFS(月次バックデータ!$J:$J,月次バックデータ!$B:$B,$B6,月次バックデータ!$E:$E,"Sales Contribution") -> 600 | S6: =ROUND(SUMIFS(月次バックデータ!$M:$M,月次バックデータ!$B:$B,$B6,月次バックデータ!$E:$E,"グロス売上"),0) -> 317 | T6: 0.9 | U6: 0.07 | V6: =ROUND(SUMIFS(月次バックデータ!$M:$M,月次バックデータ!$B:$B,$B6,月次バックデータ!$E:$E,"Sales Contribution"),0) -> 317 | W6: =V6 -> 317 | X6: 0.5 | Y6: ホンダ | Z6: - | AA6: 1005 | AB6: ・金融領域の専門人材を年間5名以上面談し、うち2名以上の内定承諾に貢献 | AC6: ・ターゲットアカウントにおいて、CFOまたは経営企画責任者との四半期ごとの戦略対話を実施 | AD6: ・新規金融機関または製造業3社へのアプローチをリードし、うち1社でM&A関連案件を受注 | AE6: ・M&A/PMI手法に関する社内勉強会を年2回開催 | AF6: ・M&Aまたは事業再編に関する論考を年1本発信 | AG6: =0.25/3 -> 0.083333333 | AH6: =0.25/3 -> 0.083333333 | AI6: =0.25/3 -> 0.083333333 | AJ6: =0.25/2 -> 0.125 | AK6: =0.25/2 -> 0.125 | AL6: =0.25/3 -> 0.083333333 | AM6: =0.25/3 -> 0.083333333 | AN6: =0.25/3 -> 0.083333333 | AO6: 0.05 | AP6: 0.05 | AQ6: 0.05 | AR6: 0.05 | AS6: 0.05 | AT6: =SUM(AG6:AS6) -> 1
B7: 齋地 禎昭 | C7: 46113 | D7: D | E7: Industry | F7: Automotive & Mobility Sector | G7: - | H7: ○ | I7: ○ | J7: No | K7: Yes | L7: 12 | M7: - | N7: - | O7: - | P7: =SUMIFS(月次バックデータ!$H:$H,月次バックデータ!$B:$B,$B7,月次バックデータ!$E:$E,"Sales Contribution") -> 200 | Q7: =SUMIFS(月次バックデータ!$I:$I,月次バックデータ!$B:$B,$B7,月次バックデータ!$E:$E,"Sales Contribution") -> 400 | R7: =SUMIFS(月次バックデータ!$J:$J,月次バックデータ!$B:$B,$B7,月次バックデータ!$E:$E,"Sales Contribution") -> 600 | S7: - | T7: - | U7: - | V7: =ROUND(SUMIFS(月次バックデータ!$M:$M,月次バックデータ!$B:$B,$B7,月次バックデータ!$E:$E,"Sales Contribution"),0) -> 267 | W7: =V7 -> 267 | X7: 0.5 | Y7: トヨタ・日立 | Z7: - | AA7: 1817 | AB7: (作成予定) | AC7: (作成予定) | AD7: (作成予定) | AE7: (作成予定) | AF7: (作成予定) | AG7: - | AH7: - | AI7: - | AJ7: =0.5/2 -> 0.25 | AK7: =0.5/2 -> 0.25 | AL7: =0.25/3 -> 0.083333333 | AM7: =0.25/3 -> 0.083333333 | AN7: =0.25/3 -> 0.083333333 | AO7: 0.05 | AP7: 0.05 | AQ7: 0.05 | AR7: 0.05 | AS7: 0.05 | AT7: =SUM(AG7:AS7) -> 1
B8: 髙橋 敦 | C8: 45931 | D8: D | E8: Industry | F8: Construction | G8: ○ | H8: ○ | I8: ○ | J8: No | K8: Yes | L8: 12 | M8: =SUMIFS(月次バックデータ!$H:$H,月次バックデータ!$B:$B,$B8,月次バックデータ!$E:$E,"グロス売上") -> 50 | N8: =SUMIFS(月次バックデータ!$I:$I,月次バックデータ!$B:$B,$B8,月次バックデータ!$E:$E,"グロス売上") -> 150 | O8: =SUMIFS(月次バックデータ!$J:$J,月次バックデータ!$B:$B,$B8,月次バックデータ!$E:$E,"グロス売上") -> 250 | P8: =SUMIFS(月次バックデータ!$H:$H,月次バックデータ!$B:$B,$B8,月次バックデータ!$E:$E,"Sales Contribution") -> 150 | Q8: =SUMIFS(月次バックデータ!$I:$I,月次バックデータ!$B:$B,$B8,月次バックデータ!$E:$E,"Sales Contribution") -> 300 | R8: =SUMIFS(月次バックデータ!$J:$J,月次バックデータ!$B:$B,$B8,月次バックデータ!$E:$E,"Sales Contribution") -> 400 | S8: =ROUND(SUMIFS(月次バックデータ!$M:$M,月次バックデータ!$B:$B,$B8,月次バックデータ!$E:$E,"グロス売上"),0) -> 133 | T8: 0.9 | U8: 0.07 | V8: =ROUND(SUMIFS(月次バックデータ!$M:$M,月次バックデータ!$B:$B,$B8,月次バックデータ!$E:$E,"Sales Contribution"),0) -> 275 | W8: =V8 -> 275 | X8: 0.5 | Y8: 竹中工務店・中部電力 | Z8: - | AA8: 252 | AB8: ・建設・不動産業界のコンサルタント経験者を年間5名以上面談し、うち2名以上の内定承諾に貢献 | AC8: ・既存建設・不動産クライアント2社において、事業責任者レベルとの四半期ごとの戦略ディスカッションを実施 | AD8: ・新規建設・不動産企業または自治体3社へのアプローチをリードし、うち1社でパイロット案件を受注 | AE8: ・建設業界の戦略策定手法に関する社内勉強会を年2回開催 | AF8: ・スマートシティまたは建設業界の未来戦略に関するホワイトペーパーを年1本発信 | AG8: =0.25/3 -> 0.083333333 | AH8: =0.25/3 -> 0.083333333 | AI8: =0.25/3 -> 0.083333333 | AJ8: =0.25/2 -> 0.125 | AK8: =0.25/2 -> 0.125 | AL8: =0.25/3 -> 0.083333333 | AM8: =0.25/3 -> 0.083333333 | AN8: =0.25/3 -> 0.083333333 | AO8: 0.05 | AP8: 0.05 | AQ8: 0.05 | AR8: 0.05 | AS8: 0.05 | AT8: =SUM(AG8:AS8) -> 1
B9: 中尾 亮 | C9: 45992 | D9: D | E9: Industry | F9: Consumer & Retail | G9: ○ | H9: ○ | I9: ○ | J9: No | K9: Yes | L9: 12 | M9: =SUMIFS(月次バックデータ!$H:$H,月次バックデータ!$B:$B,$B9,月次バックデータ!$E:$E,"グロス売上") -> 330 | N9: =SUMIFS(月次バックデータ!$I:$I,月次バックデータ!$B:$B,$B9,月次バックデータ!$E:$E,"グロス売上") -> 660 | O9: =SUMIFS(月次バックデータ!$J:$J,月次バックデータ!$B:$B,$B9,月次バックデータ!$E:$E,"グロス売上") -> 1126 | P9: =SUMIFS(月次バックデータ!$H:$H,月次バックデータ!$B:$B,$B9,月次バックデータ!$E:$E,"Sales Contribution") -> 330 | Q9: =SUMIFS(月次バックデータ!$I:$I,月次バックデータ!$B:$B,$B9,月次バックデータ!$E:$E,"Sales Contribution") -> 462 | R9: =SUMIFS(月次バックデータ!$J:$J,月次バックデータ!$B:$B,$B9,月次バックデータ!$E:$E,"Sales Contribution") -> 704 | S9: =ROUND(SUMIFS(月次バックデータ!$M:$M,月次バックデータ!$B:$B,$B9,月次バックデータ!$E:$E,"グロス売上"),0) -> 660 | T9: 0.9 | U9: 0.07 | V9: =ROUND(SUMIFS(月次バックデータ!$M:$M,月次バックデータ!$B:$B,$B9,月次バックデータ!$E:$E,"Sales Contribution"),0) -> 462 | W9: =V9 -> 462 | X9: 0.5 | Y9: 博報堂・JTB・JR北海道 | Z9: - | AA9: 332 | AB9: ・流通小売・消費財業界の戦略コンサルタント経験者を年間5名以上面談し、うち2名以上の内定承諾に貢献 | AC9: ・ターゲットアカウントにおいて、経営企画責任者レベルとの四半期ごとの戦略ディスカッションを実施 | AD9: ・ターゲットアカウントへのアプローチをリードし、パイロット案件を受注 | AE9: ・成長戦略立案手法に関する社内ワークショップを年2回開催 | AF9: ・流通小売業界の成長戦略またはサステナビリティ戦略に関するホワイトペーパーを年1本発信 | AG9: =0.25/3 -> 0.083333333 | AH9: =0.25/3 -> 0.083333333 | AI9: =0.25/3 -> 0.083333333 | AJ9: =0.25/2 -> 0.125 | AK9: =0.25/2 -> 0.125 | AL9: =0.25/3 -> 0.083333333 | AM9: =0.25/3 -> 0.083333333 | AN9: =0.25/3 -> 0.083333333 | AO9: 0.05 | AP9: 0.05 | AQ9: 0.05 | AR9: 0.05 | AS9: 0.05 | AT9: =SUM(AG9:AS9) -> 1
B10: 池田 正昭 | C10: 45778 | D10: MD | E10: Solution | F10: Corporate Finance | G10: ○ | H10: ○ | I10: ○ | J10: Yes | K10: Yes | L10: 12 | M10: =SUMIFS(月次バックデータ!$H:$H,月次バックデータ!$B:$B,$B10,月次バックデータ!$E:$E,"グロス売上") -> 209 | N10: =SUMIFS(月次バックデータ!$I:$I,月次バックデータ!$B:$B,$B10,月次バックデータ!$E:$E,"グロス売上") -> 401 | O10: =SUMIFS(月次バックデータ!$J:$J,月次バックデータ!$B:$B,$B10,月次バックデータ!$E:$E,"グロス売上") -> 506 | P10: =SUMIFS(月次バックデータ!$H:$H,月次バックデータ!$B:$B,$B10,月次バックデータ!$E:$E,"Sales Contribution") -> 209 | Q10: =SUMIFS(月次バックデータ!$I:$I,月次バックデータ!$B:$B,$B10,月次バックデータ!$E:$E,"Sales Contribution") -> 401 | R10: =SUMIFS(月次バックデータ!$J:$J,月次バックデータ!$B:$B,$B10,月次バックデータ!$E:$E,"Sales Contribution") -> 506 | S10: =ROUND(SUMIFS(月次バックデータ!$M:$M,月次バックデータ!$B:$B,$B10,月次バックデータ!$E:$E,"グロス売上"),0) -> 427 | T10: 0.9 | U10: 0.07 | V10: =ROUND(SUMIFS(月次バックデータ!$M:$M,月次バックデータ!$B:$B,$B10,月次バックデータ!$E:$E,"Sales Contribution"),0) -> 427 | W10: =V10 -> 427 | X10: 0.4 | Y10: 山九 | Z10: - | AA10: 125 | AB10: ・コーポレートファイナンスまたはM&A経験者を年間7名以上面談し、うち3名以上の内定承諾に貢献 | AC10: ・既存クライアント3社において、CFOまたはM&A責任者との四半期ごとの戦略対話を主導 | AD10: ・M&Aまたは事業再編ニーズを持つ新規クライアント4社へのアプローチをリードし、うち2社でパイロット案件を受注 | AE10: ・コーポレートファイナンス手法に関する社内トレーニングを年3回開催 | AF10: ・M&Aまたは事業戦略に関するホワイトペーパーを年2本発信 | AG10: =0.25/3 -> 0.083333333 | AH10: =0.25/3 -> 0.083333333 | AI10: =0.25/3 -> 0.083333333 | AJ10: =0.25/2 -> 0.125 | AK10: =0.25/2 -> 0.125 | AL10: =0.25/3 -> 0.083333333 | AM10: =0.25/3 -> 0.083333333 | AN10: =0.25/3 -> 0.083333333 | AO10: 0.05 | AP10: 0.05 | AQ10: 0.05 | AR10: 0.05 | AS10: 0.05 | AT10: =SUM(AG10:AS10) -> 1
B11: 北村 史郎 | C11: 46023 | D11: D | E11: Solution | F11: Corporate Finance | G11: - | H11: - | I11: ○ | J11: No | K11: Yes | L11: 12 | M11: - | N11: - | O11: - | P11: =SUMIFS(月次バックデータ!$H:$H,月次バックデータ!$B:$B,$B11,月次バックデータ!$E:$E,"Sales Contribution") -> 200 | Q11: =SUMIFS(月次バックデータ!$I:$I,月次バックデータ!$B:$B,$B11,月次バックデータ!$E:$E,"Sales Contribution") -> 200 | R11: =SUMIFS(月次バックデータ!$J:$J,月次バックデータ!$B:$B,$B11,月次バックデータ!$E:$E,"Sales Contribution") -> 200 | S11: - | T11: - | U11: - | V11: =ROUND(SUMIFS(月次バックデータ!$M:$M,月次バックデータ!$B:$B,$B11,月次バックデータ!$E:$E,"Sales Contribution"),0) -> 200 | W11: =V11 -> 200 | X11: 0.5 | Y11: - | Z11: - | AA11: - | AB11: (作成予定) | AC11: (作成予定) | AD11: (作成予定) | AE11: (作成予定) | AF11: (作成予定) | AG11: - | AH11: - | AI11: - | AJ11: - | AK11: - | AL11: =0.75/3 -> 0.25 | AM11: =0.75/3 -> 0.25 | AN11: =0.75/3 -> 0.25 | AO11: 0.05 | AP11: 0.05 | AQ11: 0.05 | AR11: 0.05 | AS11: 0.05 | AT11: =SUM(AG11:AS11) -> 1
B12: 吉田 卓史 | C12: 45931 | D12: MD | E12: Solution | F12: Cyber Security | G12: ○ | H12: - | I12: ○ | J12: No | K12: Yes | L12: 12 | M12: =SUMIFS(月次バックデータ!$H:$H,月次バックデータ!$B:$B,$B12,月次バックデータ!$E:$E,"グロス売上") -> 200 | N12: =SUMIFS(月次バックデータ!$I:$I,月次バックデータ!$B:$B,$B12,月次バックデータ!$E:$E,"グロス売上") -> 600 | O12: =SUMIFS(月次バックデータ!$J:$J,月次バックデータ!$B:$B,$B12,月次バックデータ!$E:$E,"グロス売上") -> 1100 | P12: =SUMIFS(月次バックデータ!$H:$H,月次バックデータ!$B:$B,$B12,月次バックデータ!$E:$E,"Sales Contribution") -> 200 | Q12: =SUMIFS(月次バックデータ!$I:$I,月次バックデータ!$B:$B,$B12,月次バックデータ!$E:$E,"Sales Contribution") -> 400 | R12: =SUMIFS(月次バックデータ!$J:$J,月次バックデータ!$B:$B,$B12,月次バックデータ!$E:$E,"Sales Contribution") -> 600 | S12: =ROUND(SUMIFS(月次バックデータ!$M:$M,月次バックデータ!$B:$B,$B12,月次バックデータ!$E:$E,"グロス売上"),0) -> 533 | T12: 0.9 | U12: 0.07 | V12: =ROUND(SUMIFS(月次バックデータ!$M:$M,月次バックデータ!$B:$B,$B12,月次バックデータ!$E:$E,"Sales Contribution"),0) -> 367 | W12: =V12 -> 367 | X12: 0.4 | Y12: - | Z12: - | AA12: - | AB12: ・サイバーセキュリティ専門人材（CISO、SOC経験者等）を年間7名以上面談し、うち3名以上の内定承諾に貢献 | AC12: ・新規クライアント含む3社において、CISOまたはセキュリティ責任者との四半期ごとの戦略対話を主導 | AD12: ・セキュリティ強化ニーズを持つ新規クライアント4社へのアプローチをリードし、うち2社でパイロット案件を受注 | AE12: ・サイバーセキュリティガバナンスに関する社内トレーニングを年3回開催 | AF12: ・サイバーセキュリティ戦略またはゼロトラストアーキテクチャに関するホワイトペーパーを年2本発信 | AG12: =0.5/3 -> 0.16666667 | AH12: =0.5/3 -> 0.16666667 | AI12: =0.5/3 -> 0.16666667 | AJ12: - | AK12: - | AL12: =0.25/3 -> 0.083333333 | AM12: =0.25/3 -> 0.083333333 | AN12: =0.25/3 -> 0.083333333 | AO12: 0.05 | AP12: 0.05 | AQ12: 0.05 | AR12: 0.05 | AS12: 0.05 | AT12: =SUM(AG12:AS12) -> 1
B13: 藤澤 賢成 | C13: 45748 | D13: D | E13: Industry | F13: Financial Service | G13: ○ | H13: ○ | I13: ○ | J13: Yes | K13: Yes | L13: 12 | M13: =SUMIFS(月次バックデータ!$H:$H,月次バックデータ!$B:$B,$B13,月次バックデータ!$E:$E,"グロス売上") -> 200 | N13: =SUMIFS(月次バックデータ!$I:$I,月次バックデータ!$B:$B,$B13,月次バックデータ!$E:$E,"グロス売上") -> 400 | O13: =SUMIFS(月次バックデータ!$J:$J,月次バックデータ!$B:$B,$B13,月次バックデータ!$E:$E,"グロス売上") -> 600 | P13: =SUMIFS(月次バックデータ!$H:$H,月次バックデータ!$B:$B,$B13,月次バックデータ!$E:$E,"Sales Contribution") -> 200 | Q13: =SUMIFS(月次バックデータ!$I:$I,月次バックデータ!$B:$B,$B13,月次バックデータ!$E:$E,"Sales Contribution") -> 400 | R13: =SUMIFS(月次バックデータ!$J:$J,月次バックデータ!$B:$B,$B13,月次バックデータ!$E:$E,"Sales Contribution") -> 600 | S13: =ROUND(SUMIFS(月次バックデータ!$M:$M,月次バックデータ!$B:$B,$B13,月次バックデータ!$E:$E,"グロス売上"),0) -> 467 | T13: 0.9 | U13: 0.07 | V13: =ROUND(SUMIFS(月次バックデータ!$M:$M,月次バックデータ!$B:$B,$B13,月次バックデータ!$E:$E,"Sales Contribution"),0) -> 467 | W13: =V13 -> 467 | X13: 0.5 | Y13: 三菱UFJ・野村HD | Z13: - | AA13: 400 | AB13: ・金融領域の専門人材を年間5名以上面談し、うち2名以上の内定承諾に貢献 | AC13: ・ターゲットアカウントにおいて、CROまたはCCOレベルとの四半期ごとの戦略ディスカッションを主導 | AD13: ・Basel規制対応やAML/CFT高度化ニーズを持つ新規金融機関2社へのアプローチをリードし、1件以上のパイロット案件を受注 | AE13: ・金融規制・リスク管理に関する社内勉強会を年1回以上開催し、ジュニアコンサルタントの専門性向上を支援 | AF13: ・Basel規制やAML高度化に関するホワイトペーパーまたは業界誌への寄稿を年1本発信（上期1本、下期1本） | AG13: =0.25/3 -> 0.083333333 | AH13: =0.25/3 -> 0.083333333 | AI13: =0.25/3 -> 0.083333333 | AJ13: =0.25/2 -> 0.125 | AK13: =0.25/2 -> 0.125 | AL13: =0.25/3 -> 0.083333333 | AM13: =0.25/3 -> 0.083333333 | AN13: =0.25/3 -> 0.083333333 | AO13: 0.05 | AP13: 0.05 | AQ13: 0.05 | AR13: 0.05 | AS13: 0.05 | AT13: =SUM(AG13:AS13) -> 1
B14: 大塩 大輔 | C14: 46143 | D14: MD | E14: Industry | F14: Public | G14: ○ | H14: ○ | I14: ○ | J14: No | K14: Yes | L14: 12 | M14: =SUMIFS(月次バックデータ!$H:$H,月次バックデータ!$B:$B,$B14,月次バックデータ!$E:$E,"グロス売上") -> 200 | N14: =SUMIFS(月次バックデータ!$I:$I,月次バックデータ!$B:$B,$B14,月次バックデータ!$E:$E,"グロス売上") -> 400 | O14: =SUMIFS(月次バックデータ!$J:$J,月次バックデータ!$B:$B,$B14,月次バックデータ!$E:$E,"グロス売上") -> 600 | P14: =SUMIFS(月次バックデータ!$H:$H,月次バックデータ!$B:$B,$B14,月次バックデータ!$E:$E,"Sales Contribution") -> 200 | Q14: =SUMIFS(月次バックデータ!$I:$I,月次バックデータ!$B:$B,$B14,月次バックデータ!$E:$E,"Sales Contribution") -> 400 | R14: =SUMIFS(月次バックデータ!$J:$J,月次バックデータ!$B:$B,$B14,月次バックデータ!$E:$E,"Sales Contribution") -> 600 | S14: =ROUND(SUMIFS(月次バックデータ!$M:$M,月次バックデータ!$B:$B,$B14,月次バックデータ!$E:$E,"グロス売上"),0) -> 250 | T14: 0.9 | U14: 0.07 | V14: =ROUND(SUMIFS(月次バックデータ!$M:$M,月次バックデータ!$B:$B,$B14,月次バックデータ!$E:$E,"Sales Contribution"),0) -> 250 | W14: =V14 -> 250 | X14: 0.4 | Y14: 国税庁・協会けんぽ | Z14: - | AA14: 296 | AB14: (作成予定) | AC14: (作成予定) | AD14: (作成予定) | AE14: (作成予定) | AF14: (作成予定) | AG14: =0.25/3 -> 0.083333333 | AH14: =0.25/3 -> 0.083333333 | AI14: =0.25/3 -> 0.083333333 | AJ14: =0.25/2 -> 0.125 | AK14: =0.25/2 -> 0.125 | AL14: =0.25/3 -> 0.083333333 | AM14: =0.25/3 -> 0.083333333 | AN14: =0.25/3 -> 0.083333333 | AO14: 0.05 | AP14: 0.05 | AQ14: 0.05 | AR14: 0.05 | AS14: 0.05 | AT14: =SUM(AG14:AS14) -> 1
B15: 石川 利一 | C15: 45931 | D15: D | E15: Industry | F15: Public | G15: - | H15: ○ | I15: ○ | J15: No | K15: Yes | L15: 12 | M15: - | N15: - | O15: - | P15: =SUMIFS(月次バックデータ!$H:$H,月次バックデータ!$B:$B,$B15,月次バックデータ!$E:$E,"Sales Contribution") -> 275 | Q15: =SUMIFS(月次バックデータ!$I:$I,月次バックデータ!$B:$B,$B15,月次バックデータ!$E:$E,"Sales Contribution") -> 700 | R15: =SUMIFS(月次バックデータ!$J:$J,月次バックデータ!$B:$B,$B15,月次バックデータ!$E:$E,"Sales Contribution") -> 1500 | S15: - | T15: - | U15: - | V15: =ROUND(SUMIFS(月次バックデータ!$M:$M,月次バックデータ!$B:$B,$B15,月次バックデータ!$E:$E,"Sales Contribution"),0) -> 629 | W15: =V15 -> 629 | X15: 0.5 | Y15: 厚生労働省 | Z15: - | AA15: 311 | AB15: ・アバナードメンバーのスムーズな転籍プログラムの実行 | AC15: ・官公庁または公共機関の既存クライアント2機関において、部局長レベルとの定期的なリレーション活動を実施 | AD15: ・新規官公庁または自治体2機関へのアプローチをリードし、1件以上のプロジェクトを受注 | AE15: ・官公庁ビジネスの特性や年金・社会保障制度に関する社内勉強会を年2回開催 | AF15: ・行政DXまたは社会保障政策に関する論考を年1本発信 | AG15: - | AH15: - | AI15: - | AJ15: =0.5/2 -> 0.25 | AK15: =0.5/2 -> 0.25 | AL15: =0.25/3 -> 0.083333333 | AM15: =0.25/3 -> 0.083333333 | AN15: =0.25/3 -> 0.083333333 | AO15: 0.05 | AP15: 0.05 | AQ15: 0.05 | AR15: 0.05 | AS15: 0.05 | AT15: =SUM(AG15:AS15) -> 1
B16: 玉井 俊行 | C16: 46054 | D16: D | E16: Industry | F16: Public | G16: - | H16: ○ | I16: ○ | J16: No | K16: Yes | L16: 12 | M16: - | N16: - | O16: - | P16: =SUMIFS(月次バックデータ!$H:$H,月次バックデータ!$B:$B,$B16,月次バックデータ!$E:$E,"Sales Contribution") -> 200 | Q16: =SUMIFS(月次バックデータ!$I:$I,月次バックデータ!$B:$B,$B16,月次バックデータ!$E:$E,"Sales Contribution") -> 400 | R16: =SUMIFS(月次バックデータ!$J:$J,月次バックデータ!$B:$B,$B16,月次バックデータ!$E:$E,"Sales Contribution") -> 600 | S16: - | T16: - | U16: - | V16: =ROUND(SUMIFS(月次バックデータ!$M:$M,月次バックデータ!$B:$B,$B16,月次バックデータ!$E:$E,"Sales Contribution"),0) -> 300 | W16: =V16 -> 300 | X16: 0.5 | Y16: 農林水産省・国土交通省・経済産業省 | Z16: - | AA16: 713 | AB16: (作成予定) | AC16: (作成予定) | AD16: (作成予定) | AE16: (作成予定) | AF16: (作成予定) | AG16: - | AH16: - | AI16: - | AJ16: =0.5/2 -> 0.25 | AK16: =0.5/2 -> 0.25 | AL16: =0.25/3 -> 0.083333333 | AM16: =0.25/3 -> 0.083333333 | AN16: =0.25/3 -> 0.083333333 | AO16: 0.05 | AP16: 0.05 | AQ16: 0.05 | AR16: 0.05 | AS16: 0.05 | AT16: =SUM(AG16:AS16) -> 1
B17: 上瀬 剛 | C17: 46113 | D17: D | E17: Industry | F17: Public | G17: - | H17: ○ | I17: ○ | J17: No | K17: Yes | L17: 12 | M17: - | N17: - | O17: - | P17: =SUMIFS(月次バックデータ!$H:$H,月次バックデータ!$B:$B,$B17,月次バックデータ!$E:$E,"Sales Contribution") -> 200 | Q17: =SUMIFS(月次バックデータ!$I:$I,月次バックデータ!$B:$B,$B17,月次バックデータ!$E:$E,"Sales Contribution") -> 400 | R17: =SUMIFS(月次バックデータ!$J:$J,月次バックデータ!$B:$B,$B17,月次バックデータ!$E:$E,"Sales Contribution") -> 600 | S17: - | T17: - | U17: - | V17: =ROUND(SUMIFS(月次バックデータ!$M:$M,月次バックデータ!$B:$B,$B17,月次バックデータ!$E:$E,"Sales Contribution"),0) -> 267 | W17: =V17 -> 267 | X17: 0.5 | Y17: 郵政グループ | Z17: - | AA17: 200 | AB17: (作成予定) | AC17: (作成予定) | AD17: (作成予定) | AE17: (作成予定) | AF17: (作成予定) | AG17: - | AH17: - | AI17: - | AJ17: =0.5/2 -> 0.25 | AK17: =0.5/2 -> 0.25 | AL17: =0.25/3 -> 0.083333333 | AM17: =0.25/3 -> 0.083333333 | AN17: =0.25/3 -> 0.083333333 | AO17: 0.05 | AP17: 0.05 | AQ17: 0.05 | AR17: 0.05 | AS17: 0.05 | AT17: =SUM(AG17:AS17) -> 1
B18: 加藤 節雄 | C18: 45870 | D18: MD | E18: Industry | F18: Technology | G18: ○ | H18: ○ | I18: ○ | J18: No | K18: Yes | L18: 12 | M18: =SUMIFS(月次バックデータ!$H:$H,月次バックデータ!$B:$B,$B18,月次バックデータ!$E:$E,"グロス売上") -> 500 | N18: =SUMIFS(月次バックデータ!$I:$I,月次バックデータ!$B:$B,$B18,月次バックデータ!$E:$E,"グロス売上") -> 1300 | O18: =SUMIFS(月次バックデータ!$J:$J,月次バックデータ!$B:$B,$B18,月次バックデータ!$E:$E,"グロス売上") -> 2500 | P18: =SUMIFS(月次バックデータ!$H:$H,月次バックデータ!$B:$B,$B18,月次バックデータ!$E:$E,"Sales Contribution") -> 270 | Q18: =SUMIFS(月次バックデータ!$I:$I,月次バックデータ!$B:$B,$B18,月次バックデータ!$E:$E,"Sales Contribution") -> 650 | R18: =SUMIFS(月次バックデータ!$J:$J,月次バックデータ!$B:$B,$B18,月次バックデータ!$E:$E,"Sales Contribution") -> 1400 | S18: =ROUND(SUMIFS(月次バックデータ!$M:$M,月次バックデータ!$B:$B,$B18,月次バックデータ!$E:$E,"グロス売上"),0) -> 1300 | T18: 0.9 | U18: 0.07 | V18: =ROUND(SUMIFS(月次バックデータ!$M:$M,月次バックデータ!$B:$B,$B18,月次バックデータ!$E:$E,"Sales Contribution"),0) -> 650 | W18: =V18 -> 650 | X18: 0.4 | Y18: NEC | Z18: - | AA18: 1179 | AB18: ・テクノロジー領域のコンサルタント経験者を年間7名以上面談し、うち3名以上の内定承諾に貢献 | AC18: ・新規クライアント含む3社において、CIOまたはIT戦略責任者との四半期ごとの戦略対話を主導 | AD18: ・ERP/DXニーズを持つ新規クライアント4社へのアプローチをリードし、うち2社でパイロット案件を受注 | AE18: ・ERP導入手法または生成AI活用に関する社内トレーニングを年3回開催 | AF18: ・DXまたはERP導入に関するホワイトペーパーを年2本発信 | AG18: =0.25/3 -> 0.083333333 | AH18: =0.25/3 -> 0.083333333 | AI18: =0.25/3 -> 0.083333333 | AJ18: =0.25/2 -> 0.125 | AK18: =0.25/2 -> 0.125 | AL18: =0.25/3 -> 0.083333333 | AM18: =0.25/3 -> 0.083333333 | AN18: =0.25/3 -> 0.083333333 | AO18: 0.05 | AP18: 0.05 | AQ18: 0.05 | AR18: 0.05 | AS18: 0.05 | AT18: =SUM(AG18:AS18) -> 1
B19: 藤川 真一 | C19: 46054 | D19: MD | E19: Industry | F19: Technology | G19: - | H19: ○ | I19: ○ | J19: No | K19: Yes | L19: 12 | M19: - | N19: - | O19: - | P19: =SUMIFS(月次バックデータ!$H:$H,月次バックデータ!$B:$B,$B19,月次バックデータ!$E:$E,"Sales Contribution") -> 353 | Q19: =SUMIFS(月次バックデータ!$I:$I,月次バックデータ!$B:$B,$B19,月次バックデータ!$E:$E,"Sales Contribution") -> 1291 | R19: =SUMIFS(月次バックデータ!$J:$J,月次バックデータ!$B:$B,$B19,月次バックデータ!$E:$E,"Sales Contribution") -> 1528 | S19: - | T19: - | U19: - | V19: =ROUND(SUMIFS(月次バックデータ!$M:$M,月次バックデータ!$B:$B,$B19,月次バックデータ!$E:$E,"Sales Contribution"),0) -> 1291 | W19: =V19 -> 1291 | X19: 0.4 | Y19: パナソニック | Z19: - | AA19: 215 | AB19: (作成予定) | AC19: (作成予定) | AD19: (作成予定) | AE19: (作成予定) | AF19: (作成予定) | AG19: - | AH19: - | AI19: - | AJ19: =0.5/2 -> 0.25 | AK19: =0.5/2 -> 0.25 | AL19: =0.25/3 -> 0.083333333 | AM19: =0.25/3 -> 0.083333333 | AN19: =0.25/3 -> 0.083333333 | AO19: 0.05 | AP19: 0.05 | AQ19: 0.05 | AR19: 0.05 | AS19: 0.05 | AT19: =SUM(AG19:AS19) -> 1
B20: 福島 毅 | C20: 45597 | D20: D | E20: Industry | F20: Technology | G20: - | H20: - | I20: ○ | J20: Yes | K20: Yes | L20: 12 | M20: - | N20: - | O20: - | P20: =SUMIFS(月次バックデータ!$H:$H,月次バックデータ!$B:$B,$B20,月次バックデータ!$E:$E,"Sales Contribution") -> 200 | Q20: =SUMIFS(月次バックデータ!$I:$I,月次バックデータ!$B:$B,$B20,月次バックデータ!$E:$E,"Sales Contribution") -> 300 | R20: =SUMIFS(月次バックデータ!$J:$J,月次バックデータ!$B:$B,$B20,月次バックデータ!$E:$E,"Sales Contribution") -> 0 | S20: - | T20: - | U20: - | V20: =ROUND(SUMIFS(月次バックデータ!$M:$M,月次バックデータ!$B:$B,$B20,月次バックデータ!$E:$E,"Sales Contribution"),0) -> 300 | W20: =V20 -> 300 | X20: 0.5 | Y20: - | Z20: - | AA20: - | AB20: ・DX/業務改革領域の経験者（PMO、BPRスペシャリスト等）を年間5名以上面談し、うち2名以上の内定承諾に貢献 | AC20: ・ターゲットアカウントにおいて、CIOまたはCDOレベルとの定期的な関係構築を推進 | AD20: ・大規模プログラム推進や業務改革ニーズを持つ新規クライアント3社へアプローチし、うち1社でパイロット案件を受注 | AE20: ・大規模プログラム推進手法に関する社内トレーニングを年1回開催し、PM・PMOスキルの底上げを図る | AF20: ・DX推進やプログラムマネジメントに関するホワイトペーパーを年1本発信 | AG20: - | AH20: - | AI20: - | AJ20: - | AK20: - | AL20: =0.75/3 -> 0.25 | AM20: =0.75/3 -> 0.25 | AN20: =0.75/3 -> 0.25 | AO20: 0.05 | AP20: 0.05 | AQ20: 0.05 | AR20: 0.05 | AS20: 0.05 | AT20: =SUM(AG20:AS20) -> 1
B21: 渋谷 賢吾 | C21: 45717 | D21: MD | E21: Industry | F21: Telecom | G21: ○ | H21: ○ | I21: ○ | J21: Yes | K21: Yes | L21: 12 | M21: =SUMIFS(月次バックデータ!$H:$H,月次バックデータ!$B:$B,$B21,月次バックデータ!$E:$E,"グロス売上") -> 150 | N21: =SUMIFS(月次バックデータ!$I:$I,月次バックデータ!$B:$B,$B21,月次バックデータ!$E:$E,"グロス売上") -> 400 | O21: =SUMIFS(月次バックデータ!$J:$J,月次バックデータ!$B:$B,$B21,月次バックデータ!$E:$E,"グロス売上") -> 1000 | P21: =SUMIFS(月次バックデータ!$H:$H,月次バックデータ!$B:$B,$B21,月次バックデータ!$E:$E,"Sales Contribution") -> 150 | Q21: =SUMIFS(月次バックデータ!$I:$I,月次バックデータ!$B:$B,$B21,月次バックデータ!$E:$E,"Sales Contribution") -> 400 | R21: =SUMIFS(月次バックデータ!$J:$J,月次バックデータ!$B:$B,$B21,月次バックデータ!$E:$E,"Sales Contribution") -> 1000 | S21: =ROUND(SUMIFS(月次バックデータ!$M:$M,月次バックデータ!$B:$B,$B21,月次バックデータ!$E:$E,"グロス売上"),0) -> 650 | T21: 0.9 | U21: 0.07 | V21: =ROUND(SUMIFS(月次バックデータ!$M:$M,月次バックデータ!$B:$B,$B21,月次バックデータ!$E:$E,"Sales Contribution"),0) -> 650 | W21: =V21 -> 650 | X21: 0.4 | Y21: NTTデータ・KDDI | Z21: - | AA21: 3879 | AB21: ・通信業界の戦略コンサルタント経験者を年間7名以上面談し、うち3名以上の内定承諾に貢献 | AC21: ・既存クライアントにおいて、部門責任者またはCXOレベルとの四半期ごとの戦略対話を主導 | AD21: ・既存顧客及び関連会社へのアプローチをリードし、うち2社で大型案件を受注 | AE21: ・通信業界の事業戦略立案手法に関する社内トレーニングを年3回開催 | AF21: ・Future of Telecomシリーズに類する通信業界の未来デザインに関するホワイトペーパーを年1本発信 | AG21: =0.25/3 -> 0.083333333 | AH21: =0.25/3 -> 0.083333333 | AI21: =0.25/3 -> 0.083333333 | AJ21: =0.25/2 -> 0.125 | AK21: =0.25/2 -> 0.125 | AL21: =0.25/3 -> 0.083333333 | AM21: =0.25/3 -> 0.083333333 | AN21: =0.25/3 -> 0.083333333 | AO21: 0.05 | AP21: 0.05 | AQ21: 0.05 | AR21: 0.05 | AS21: 0.05 | AT21: =SUM(AG21:AS21) -> 1
B22: 深谷 匡隆 | C22: 45870 | D22: MD | E22: Industry | F22: Transportation | G22: ○ | H22: ○ | I22: ○ | J22: No | K22: Yes | L22: 12 | M22: =SUMIFS(月次バックデータ!$H:$H,月次バックデータ!$B:$B,$B22,月次バックデータ!$E:$E,"グロス売上") -> 400 | N22: =SUMIFS(月次バックデータ!$I:$I,月次バックデータ!$B:$B,$B22,月次バックデータ!$E:$E,"グロス売上") -> 600 | O22: =SUMIFS(月次バックデータ!$J:$J,月次バックデータ!$B:$B,$B22,月次バックデータ!$E:$E,"グロス売上") -> 1000 | P22: =SUMIFS(月次バックデータ!$H:$H,月次バックデータ!$B:$B,$B22,月次バックデータ!$E:$E,"Sales Contribution") -> 200 | Q22: =SUMIFS(月次バックデータ!$I:$I,月次バックデータ!$B:$B,$B22,月次バックデータ!$E:$E,"Sales Contribution") -> 400 | R22: =SUMIFS(月次バックデータ!$J:$J,月次バックデータ!$B:$B,$B22,月次バックデータ!$E:$E,"Sales Contribution") -> 600 | S22: =ROUND(SUMIFS(月次バックデータ!$M:$M,月次バックデータ!$B:$B,$B22,月次バックデータ!$E:$E,"グロス売上"),0) -> 600 | T22: 0.9 | U22: 0.07 | V22: =ROUND(SUMIFS(月次バックデータ!$M:$M,月次バックデータ!$B:$B,$B22,月次バックデータ!$E:$E,"Sales Contribution"),0) -> 400 | W22: =V22 -> 400 | X22: 0.4 | Y22: ANA・JAL | Z22: - | AA22: 564 | AB22: ・運輸業界に専門性のある戦略コンサルタント経験者を年間7名以上面談し、うち3名以上の内定承諾に貢献 | AC22: ・既存クライアント3社において、経営トップまたは事業責任者レベルとの四半期ごとの戦略ディスカッションを主導 | AD22: ・新規クライアント5社へのアプローチをリードし、うち3社でパイロット案件を受注 | AE22: ・運輸業界の事業戦略立案手法に関する社内トレーニングを年3回開催 | AF22: ・製造業または小売業の成長戦略に関するホワイトペーパーを年1本発信 | AG22: =0.25/3 -> 0.083333333 | AH22: =0.25/3 -> 0.083333333 | AI22: =0.25/3 -> 0.083333333 | AJ22: =0.25/2 -> 0.125 | AK22: =0.25/2 -> 0.125 | AL22: =0.25/3 -> 0.083333333 | AM22: =0.25/3 -> 0.083333333 | AN22: =0.25/3 -> 0.083333333 | AO22: 0.05 | AP22: 0.05 | AQ22: 0.05 | AR22: 0.05 | AS22: 0.05 | AT22: =SUM(AG22:AS22) -> 1
B23: 中澤 可武 | C23: 46235 | D23: MD | E23: Solution | F23: GRC | G23: ○ | H23: - | I23: ○ | J23: No | K23: Yes | L23: 12 | M23: =SUMIFS(月次バックデータ!$H:$H,月次バックデータ!$B:$B,$B23,月次バックデータ!$E:$E,"グロス売上") -> 0 | N23: =SUMIFS(月次バックデータ!$I:$I,月次バックデータ!$B:$B,$B23,月次バックデータ!$E:$E,"グロス売上") -> 150 | O23: =SUMIFS(月次バックデータ!$J:$J,月次バックデータ!$B:$B,$B23,月次バックデータ!$E:$E,"グロス売上") -> 300 | P23: =SUMIFS(月次バックデータ!$H:$H,月次バックデータ!$B:$B,$B23,月次バックデータ!$E:$E,"Sales Contribution") -> 0 | Q23: =SUMIFS(月次バックデータ!$I:$I,月次バックデータ!$B:$B,$B23,月次バックデータ!$E:$E,"Sales Contribution") -> 150 | R23: =SUMIFS(月次バックデータ!$J:$J,月次バックデータ!$B:$B,$B23,月次バックデータ!$E:$E,"Sales Contribution") -> 300 | S23: =ROUND(SUMIFS(月次バックデータ!$M:$M,月次バックデータ!$B:$B,$B23,月次バックデータ!$E:$E,"グロス売上"),0) -> 150 | T23: 0.9 | U23: 0.07 | V23: =ROUND(SUMIFS(月次バックデータ!$M:$M,月次バックデータ!$B:$B,$B23,月次バックデータ!$E:$E,"Sales Contribution"),0) -> 150 | W23: =V23 -> 150 | X23: 0.4 | Y23: - | Z23: - | AA23: - | AB23: (作成予定) | AC23: (作成予定) | AD23: (作成予定) | AE23: (作成予定) | AF23: (作成予定) | AG23: =0.5/3 -> 0.16666667 | AH23: =0.5/3 -> 0.16666667 | AI23: =0.5/3 -> 0.16666667 | AJ23: - | AK23: - | AL23: =0.25/3 -> 0.083333333 | AM23: =0.25/3 -> 0.083333333 | AN23: =0.25/3 -> 0.083333333 | AO23: 0.05 | AP23: 0.05 | AQ23: 0.05 | AR23: 0.05 | AS23: 0.05 | AT23: =SUM(AG23:AS23) -> 1
B24: 十河 | C24: 46296 | D24: D | E24: Solution | F24: GRC

Sheet FY27目標設定_70億ベース
B2: 氏名 | C2: 入社年月日 | D2: Title | E2: Organization | F2: 所属Pracice | G2: KPI該当有無の整理 | J2: FY26対象 | K2: FY27対象 | M2: PracticeリーダーKPI | P2: MD・D 個人KPI | S2: PracticeリーダーKPI | V2: MD・D 個人KPI | AA2: Accountリーダー KPI | AD2: 非財務KPI | AI2: Weight
M3: ネット売上 | P3: Sales Contribution | S3: ネット売上 | T3: 組織稼働率 | U3: グロスDiscount率 | V3: Sales Contribution | W3: Sales Contribution | X3: Sales Contribution(採用判定) | Y3: Managed Revenue | Z3: 有償稼働率 | AI3: PracticeリーダーKPI | AL3: Account リーダー | AN3: MD・D個人 | AQ3: 非財務 | AV3: 合計
G4: Practiceリーダー KPI | H4: Accountリーダー KPI | I4: MDD KPI | J4: 対象有無 | K4: 対象有無 | L4: 評価期間 | M4: 入社1年目 | N4: 入社2年目 | O4: 入社3年目 | P4: 入社1年目 | Q4: 入社2年目 | R4: 入社3年目 | S4: FY27 | T4: FY27 | U4: FY27 | V4: FY27 | W4: FY27 | X4: FY27 | Y4: FY27 | Z4: FY27 | AA4: アカウント名 | AB4: アカウント受注額 | AC4: アカウント売上高 | AD4: 採用 | AE4: 顧客リレーション | AF4: リード創出 | AG4: 教育／育成 | AH4: Thought Leadership | AI4: グロス売上 | AJ4: 有償稼働率(組織トータル) | AK4: グロスDiscount率 | AL4: アカウント受注額 | AM4: アカウント売上高 | AN4: Sales Contribution | AO4: Managed Revenue | AP4: 有償稼働率(個人) | AQ4: 採用 | AR4: セールス前工程 | AS4: 教育／育成 | AT4: Thought Leadership | AU4: AI活用
B5: 高橋 聖 | C5: 46082 | D5: D | E5: Solution | F5: AI & Data | G5: ○ | H5: - | I5: ○ | J5: No | K5: Yes | L5: 12 | M5: =SUMIFS(月次バックデータ!$H:$H,月次バックデータ!$B:$B,$B5,月次バックデータ!$E:$E,"グロス売上") -> 230 | N5: =SUMIFS(月次バックデータ!$I:$I,月次バックデータ!$B:$B,$B5,月次バックデータ!$E:$E,"グロス売上") -> 600 | O5: =SUMIFS(月次バックデータ!$J:$J,月次バックデータ!$B:$B,$B5,月次バックデータ!$E:$E,"グロス売上") -> 840 | P5: =SUMIFS(月次バックデータ!$H:$H,月次バックデータ!$B:$B,$B5,月次バックデータ!$E:$E,"Sales Contribution") -> 230 | Q5: =SUMIFS(月次バックデータ!$I:$I,月次バックデータ!$B:$B,$B5,月次バックデータ!$E:$E,"Sales Contribution") -> 600 | R5: =SUMIFS(月次バックデータ!$J:$J,月次バックデータ!$B:$B,$B5,月次バックデータ!$E:$E,"Sales Contribution") -> 840 | S5: =IF(G5="○",VLOOKUP(F5,Practice別!B:O,14,FALSE),"-") -> 444 | T5: 1 | U5: 0.07 | V5: =ROUND(SUMIFS(月次バックデータ!$M:$M,月次バックデータ!$B:$B,$B5,月次バックデータ!$E:$E,"Sales Contribution"),0) -> 600 | W5: =$S5 -> 444 | X5: =IF(W5>V5,W5,V5) -> 600 | Y5: =V5 -> 600 | Z5: 0.5 | AA5: - | AB5: - | AC5: - | AD5: ・データサイエンティスト、AIエンジニア、データ戦略コンサルタント等のAI/データ領域専門人材を年間5名以上面談し、うち2名以上の内定承諾に貢献 ・AI & Data Practiceの採用計画策定をPracticeリーダーとして主導 | AE5: ・ターゲットアカウントにおいて、CDOまたはCIOレベルとの四半期ごとの戦略ディスカッションを実施 ・生成AI活用やデータ利活用・データガバナンスに関する情報提供セッションを年4回以上実施 | AF5: ・生成AI/データ活用ニーズを持つ新規クライアント3社へのアプローチをリードし、うち1社でPoCまたはパイロット案件を受注 ・Industry Practiceと連携し、AI/データ活用事例を組み込んだクロスセル提案を四半期ごとに実施 | AG5: ・生成AI・データ分析手法に関する社内勉強会を年2回開催し、ファーム全体のAIリテラシー向上を支援 ・プロジェクトにおいて2名以上のメンバーへのOJT指導を実施 | AH5: ・生成AIまたはデータ利活用に関するホワイトペーパーを年1本発信 ・AI/データ関連カンファレンスまたはウェビナーへの登壇を年1回以上実施 | AI5: =0.5/3 -> 0.16666667 | AJ5: =0.5/3 -> 0.16666667 | AK5: =0.5/3 -> 0.16666667 | AL5: - | AM5: - | AN5: =0.25/3 -> 0.083333333 | AO5: =0.25/3 -> 0.083333333 | AP5: =0.25/3 -> 0.083333333 | AQ5: 0.05 | AR5: 0.05 | AS5: 0.05 | AT5: 0.05 | AU5: 0.05 | AV5: =SUM(AI5:AU5) -> 1
B6: 高橋 新 | C6: 46023 | D6: D | E6: Industry | F6: Automotive & Mobility Sector | G6: ○ | H6: ○ | I6: ○ | J6: No | K6: Yes | L6: 12 | M6: =SUMIFS(月次バックデータ!$H:$H,月次バックデータ!$B:$B,$B6,月次バックデータ!$E:$E,"グロス売上") -> 200 | N6: =SUMIFS(月次バックデータ!$I:$I,月次バックデータ!$B:$B,$B6,月次バックデータ!$E:$E,"グロス売上") -> 400 | O6: =SUMIFS(月次バックデータ!$J:$J,月次バックデータ!$B:$B,$B6,月次バックデータ!$E:$E,"グロス売上") -> 600 | P6: =SUMIFS(月次バックデータ!$H:$H,月次バックデータ!$B:$B,$B6,月次バックデータ!$E:$E,"Sales Contribution") -> 200 | Q6: =SUMIFS(月次バックデータ!$I:$I,月次バックデータ!$B:$B,$B6,月次バックデータ!$E:$E,"Sales Contribution") -> 400 | R6: =SUMIFS(月次バックデータ!$J:$J,月次バックデータ!$B:$B,$B6,月次バックデータ!$E:$E,"Sales Contribution") -> 600 | S6: =IF(G6="○",VLOOKUP(F6,Practice別!B:O,14,FALSE),"-") -> 366 | T6: 1 | U6: 0.07 | V6: =ROUND(SUMIFS(月次バックデータ!$M:$M,月次バックデータ!$B:$B,$B6,月次バックデータ!$E:$E,"Sales Contribution"),0) -> 317 | W6: =$S6/2 -> 183 | X6: =IF(W6>V6,W6,V6) -> 317 | Y6: =V6 -> 317 | Z6: 0.5 | AA6: ホンダ | AB6: - | AC6: 1005 | AD6: ・金融領域の専門人材を年間5名以上面談し、うち2名以上の内定承諾に貢献 | AE6: ・ターゲットアカウントにおいて、CFOまたは経営企画責任者との四半期ごとの戦略対話を実施 ・M&A戦略やグローバル経営に関する情報提供セッションを年4回以上開催 | AF6: ・新規金融機関または製造業3社へのアプローチをリードし、うち1社でM&A関連案件を受注 ・事業再編やカーブアウト事例を活用した提案活動を四半期ごとに実施 | AG6: ・M&A/PMI手法に関する社内勉強会を年2回開催 ・プロジェクトにおいて2名以上のメンバーへのOJT指導を実施 | AH6: ・M&Aまたは事業再編に関する論考を年1本発信 ・M&Aフォーラムまたは金融業界セミナーへの登壇を年1回以上実施 | AI6: =0.25/3 -> 0.083333333 | AJ6: =0.25/3 -> 0.083333333 | AK6: =0.25/3 -> 0.083333333 | AL6: =0.25/2 -> 0.125 | AM6: =0.25/2 -> 0.125 | AN6: =0.25/3 -> 0.083333333 | AO6: =0.25/3 -> 0.083333333 | AP6: =0.25/3 -> 0.083333333 | AQ6: 0.05 | AR6: 0.05 | AS6: 0.05 | AT6: 0.05 | AU6: 0.05 | AV6: =SUM(AI6:AU6) -> 1
B7: 齋地 禎昭 | C7: 46113 | D7: D | E7: Industry | F7: Automotive & Mobility Sector | G7: - | H7: ○ | I7: ○ | J7: No | K7: Yes | L7: 12 | M7: - | N7: - | O7: - | P7: =SUMIFS(月次バックデータ!$H:$H,月次バックデータ!$B:$B,$B7,月次バックデータ!$E:$E,"Sales Contribution") -> 200 | Q7: =SUMIFS(月次バックデータ!$I:$I,月次バックデータ!$B:$B,$B7,月次バックデータ!$E:$E,"Sales Contribution") -> 400 | R7: =SUMIFS(月次バックデータ!$J:$J,月次バックデータ!$B:$B,$B7,月次バックデータ!$E:$E,"Sales Contribution") -> 600 | S7: =IF(G7="○",VLOOKUP(F7,Practice別!B:O,14,FALSE),"-") -> - | T7: - | U7: - | V7: =ROUND(SUMIFS(月次バックデータ!$M:$M,月次バックデータ!$B:$B,$B7,月次バックデータ!$E:$E,"Sales Contribution"),0) -> 267 | W7: =$S6/2 -> 183 | X7: =IF(W7>V7,W7,V7) -> 267 | Y7: - | Z7: - | AA7: トヨタ・日立 | AB7: - | AC7: 1817 | AD7: ・自動車・モビリティ業界の経験者（OEM/サプライヤー出身者、業界コンサルタント等）を年間5名以上面談し、うち2名以上の内定承諾に貢献 | AE7: ・ターゲットアカウント（トヨタ・日立）において、事業部長または経営企画責任者レベルとの四半期ごとの戦略ディスカッションを実施 ・CASE/SDV動向やサプライチェーン再編に関する情報提供セッションを年4回以上実施 | AF7: ・新規自動車OEM・サプライヤーまたはモビリティ関連企業3社へのアプローチをリードし、うち1社でパイロット案件を受注 ・SDV・電動化・モビリティサービス事例を活用した提案活動を四半期ごとに実施 | AG7: ・自動車業界の事業構造・CASE動向に関する社内勉強会を年2回開催 ・プロジェクトにおいて2名以上のメンバーへのOJT指導を実施 | AH7: ・SDVまたはモビリティ業界の未来戦略に関する論考を年1本発信 ・自動車・モビリティ業界セミナーへの登壇を年1回以上実施 | AI7: - | AJ7: - | AK7: - | AL7: =0.5/2 -> 0.25 | AM7: =0.5/2 -> 0.25 | AN7: 0.25 | AO7: - | AP7: - | AQ7: 0.05 | AR7: 0.05 | AS7: 0.05 | AT7: 0.05 | AU7: 0.05 | AV7: =SUM(AI7:AU7) -> 1
B8: 髙橋 敦 | C8: 45931 | D8: D | E8: Industry | F8: Construction | G8: ○ | H8: ○ | I8: ○ | J8: No | K8: Yes | L8: 12 | M8: =SUMIFS(月次バックデータ!$H:$H,月次バックデータ!$B:$B,$B8,月次バックデータ!$E:$E,"グロス売上") -> 50 | N8: =SUMIFS(月次バックデータ!$I:$I,月次バックデータ!$B:$B,$B8,月次バックデータ!$E:$E,"グロス売上") -> 150 | O8: =SUMIFS(月次バックデータ!$J:$J,月次バックデータ!$B:$B,$B8,月次バックデータ!$E:$E,"グロス売上") -> 250 | P8: =SUMIFS(月次バックデータ!$H:$H,月次バックデータ!$B:$B,$B8,月次バックデータ!$E:$E,"Sales Contribution") -> 150 | Q8: =SUMIFS(月次バックデータ!$I:$I,月次バックデータ!$B:$B,$B8,月次バックデータ!$E:$E,"Sales Contribution") -> 300 | R8: =SUMIFS(月次バックデータ!$J:$J,月次バックデータ!$B:$B,$B8,月次バックデータ!$E:$E,"Sales Contribution") -> 400 | S8: =IF(G8="○",VLOOKUP(F8,Practice別!B:O,14,FALSE),"-") -> 365 | T8: 1 | U8: 0.07 | V8: =ROUND(SUMIFS(月次バックデータ!$M:$M,月次バックデータ!$B:$B,$B8,月次バックデータ!$E:$E,"Sales Contribution"),0) -> 275 | W8: =$S8 -> 365 | X8: =IF(W8>V8,W8,V8) -> 365 | Y8: =V8 -> 275 | Z8: 0.5 | AA8: 竹中工務店・中部電力 | AB8: - | AC8: 252 | AD8: ・建設・不動産業界のコンサルタント経験者を年間5名以上面談し、うち2名以上の内定承諾に貢献 | AE8: ・既存建設・不動産クライアント2社において、事業責任者レベルとの四半期ごとの戦略ディスカッションを実施 ・スマートシティ戦略やモビリティサービスに関する情報提供セッションを年4回以上開催 | AF8: ・新規建設・不動産企業または自治体3社へのアプローチをリードし、うち1社でパイロット案件を受注 ・スマートシティ構想や未来洞察レポートを活用した提案活動を実施 | AG8: ・建設業界の戦略策定手法に関する社内勉強会を年2回開催 ・プロジェクトにおいて2名以上のメンバーへのOJT指導を実施 | AH8: ・スマートシティまたは建設業界の未来戦略に関するホワイトペーパーを年1本発信 ・スマートシティフォーラムまたは建設業界セミナーへの登壇を年1回以上実施 | AI8: =0.25/3 -> 0.083333333 | AJ8: =0.25/3 -> 0.083333333 | AK8: =0.25/3 -> 0.083333333 | AL8: =0.25/2 -> 0.125 | AM8: =0.25/2 -> 0.125 | AN8: =0.25/3 -> 0.083333333 | AO8: =0.25/3 -> 0.083333333 | AP8: =0.25/3 -> 0.083333333 | AQ8: 0.05 | AR8: 0.05 | AS8: 0.05 | AT8: 0.05 | AU8: 0.05 | AV8: =SUM(AI8:AU8) -> 1
B9: 中尾 亮 | C9: 45992 | D9: D | E9: Industry | F9: Consumer & Retail | G9: ○ | H9: ○ | I9: ○ | J9: No | K9: Yes | L9: 12 | M9: =SUMIFS(月次バックデータ!$H:$H,月次バックデータ!$B:$B,$B9,月次バックデータ!$E:$E,"グロス売上") -> 330 | N9: =SUMIFS(月次バックデータ!$I:$I,月次バックデータ!$B:$B,$B9,月次バックデータ!$E:$E,"グロス売上") -> 660 | O9: =SUMIFS(月次バックデータ!$J:$J,月次バックデータ!$B:$B,$B9,月次バックデータ!$E:$E,"グロス売上") -> 1126 | P9: =SUMIFS(月次バックデータ!$H:$H,月次バックデータ!$B:$B,$B9,月次バックデータ!$E:$E,"Sales Contribution") -> 330 | Q9: =SUMIFS(月次バックデータ!$I:$I,月次バックデータ!$B:$B,$B9,月次バックデータ!$E:$E,"Sales Contribution") -> 462 | R9: =SUMIFS(月次バックデータ!$J:$J,月次バックデータ!$B:$B,$B9,月次バックデータ!$E:$E,"Sales Contribution") -> 704 | S9: =IF(G9="○",VLOOKUP(F9,Practice別!B:O,14,FALSE),"-") -> 312 | T9: 1 | U9: 0.07 | V9: =ROUND(SUMIFS(月次バックデータ!$M:$M,月次バックデータ!$B:$B,$B9,月次バックデータ!$E:$E,"Sales Contribution"),0) -> 462 | W9: =$S9 -> 312 | X9: =IF(W9>V9,W9,V9) -> 462 | Y9: =V9 -> 462 | Z9: 0.5 | AA9: 博報堂・JTB・JR北海道 | AB9: - | AC9: 332 | AD9: ・流通小売・消費財業界の戦略コンサルタント経験者を年間5名以上面談し、うち2名以上の内定承諾に貢献 | AE9: ・ターゲットアカウントにおいて、経営企画責任者レベルとの四半期ごとの戦略ディスカッションを実施 ・サステナビリティ戦略やサプライチェーン改革に関する情報提供セッションを年3回以上実施 | AF9: ・ターゲットアカウントへのアプローチをリードし、パイロット案件を受注 ・業界トレンド分析やベンチマーク情報を活用した提案活動を四半期ごとに実施 | AG9: ・成長戦略立案手法に関する社内ワークショップを年2回開催 ・プロジェクトにおいて3名以上のジュニアコンサルタントへのOJT指導を実施し、戦略思考力を育成 | AH9: ・流通小売業界の成長戦略またはサステナビリティ戦略に関するホワイトペーパーを年1本発信 ・業界セミナーまたはフォーラムへの登壇を年1回以上実施 | AI9: =0.25/3 -> 0.083333333 | AJ9: =0.25/3 -> 0.083333333 | AK9: =0.25/3 -> 0.083333333 | AL9: =0.25/2 -> 0.125 | AM9: =0.25/2 -> 0.125 | AN9: =0.25/3 -> 0.083333333 | AO9: =0.25/3 -> 0.083333333 | AP9: =0.25/3 -> 0.083333333 | AQ9: 0.05 | AR9: 0.05 | AS9: 0.05 | AT9: 0.05 | AU9: 0.05 | AV9: =SUM(AI9:AU9) -> 1
B10: 池田 正昭 | C10: 45778 | D10: MD | E10: Solution | F10: Corporate Finance | G10: ○ | H10: ○ | I10: ○ | J10: Yes | K10: Yes | L10: 12 | M10: =SUMIFS(月次バックデータ!$H:$H,月次バックデータ!$B:$B,$B10,月次バックデータ!$E:$E,"グロス売上") -> 209 | N10: =SUMIFS(月次バックデータ!$I:$I,月次バックデータ!$B:$B,$B10,月次バックデータ!$E:$E,"グロス売上") -> 401 | O10: =SUMIFS(月次バックデータ!$J:$J,月次バックデータ!$B:$B,$B10,月次バックデータ!$E:$E,"グロス売上") -> 506 | P10: =SUMIFS(月次バックデータ!$H:$H,月次バックデータ!$B:$B,$B10,月次バックデータ!$E:$E,"Sales Contribution") -> 209 | Q10: =SUMIFS(月次バックデータ!$I:$I,月次バックデータ!$B:$B,$B10,月次バックデータ!$E:$E,"Sales Contribution") -> 401 | R10: =SUMIFS(月次バックデータ!$J:$J,月次バックデータ!$B:$B,$B10,月次バックデータ!$E:$E,"Sales Contribution") -> 506 | S10: =IF(G10="○",VLOOKUP(F10,Practice別!B:O,14,FALSE),"-") -> 546 | T10: 1 | U10: 0.07 | V10: =ROUND(SUMIFS(月次バックデータ!$M:$M,月次バックデータ!$B:$B,$B10,月次バックデータ!$E:$E,"Sales Contribution"),0) -> 427 | W10: =$S10 -> 546 | X10: =IF(W10>V10,W10,V10) -> 546 | Y10: =V10 -> 427 | Z10: 0.4 | AA10: 山九 | AB10: - | AC10: 125 | AD10: ・コーポレートファイナンスまたはM&A経験者を年間7名以上面談し、うち3名以上の内定承諾に貢献 ・ファイナンス系キャリアセミナーまたはネットワーキングイベントに2回以上参画 | AE10: ・既存クライアント3社において、CFOまたはM&A責任者との四半期ごとの戦略対話を主導 ・M&A市場動向やバリュエーション手法に関する情報提供セッションを年3回以上実施 | AF10: ・M&Aまたは事業再編ニーズを持つ新規クライアント4社へのアプローチをリードし、うち2社でパイロット案件を受注 ・デューデリジェンスやPMI事例を活用した提案活動を四半期ごとに実施 | AG10: ・コーポレートファイナンス手法に関する社内トレーニングを年3回開催 ・Practice内メンバー3名以上に対する定期的なメンタリングを実施 | AH10: ・M&Aまたは事業戦略に関するホワイトペーパーを年2本発信 ・M&Aカンファレンスまたは経営フォーラムへの登壇を年1回以上実施 | AI10: =0.25/3 -> 0.083333333 | AJ10: =0.25/3 -> 0.083333333 | AK10: =0.25/3 -> 0.083333333 | AL10: =0.25/2 -> 0.125 | AM10: =0.25/2 -> 0.125 | AN10: =0.25/3 -> 0.083333333 | AO10: =0.25/3 -> 0.083333333 | AP10: =0.25/3 -> 0.083333333 | AQ10: 0.05 | AR10: 0.05 | AS10: 0.05 | AT10: 0.05 | AU10: 0.05 | AV10: =SUM(AI10:AU10) -> 1
B11: 北村 史郎 | C11: 46023 | D11: D | E11: Solution | F11: Corporate Finance | G11: - | H11: - | I11: ○ | J11: No | K11: No | L11: 12 | M11: - | N11: - | O11: - | P11: - | Q11: - | R11: - | S11: =IF(G11="○",VLOOKUP(F11,Practice別!B:O,14,FALSE),"-") -> - | T11: - | U11: - | V11: - | W11: - | X11: =IF(W11>V11,W11,V11) -> - | Y11: - | Z11: - | AA11: - | AB11: - | AC11: - | AD11: (作成予定) | AE11: (作成予定) | AF11: (作成予定) | AG11: (作成予定) | AH11: (作成予定) | AI11: - | AJ11: - | AK11: - | AL11: - | AM11: - | AN11: =0.75/3 -> 0.25 | AO11: =0.75/3 -> 0.25 | AP11: =0.75/3 -> 0.25 | AQ11: 0.05 | AR11: 0.05 | AS11: 0.05 | AT11: 0.05 | AU11: 0.05 | AV11: =SUM(AI11:AU11) -> 1
B12: 吉田 卓史 | C12: 45931 | D12: MD | E12: Solution | F12: Cyber Security | G12: ○ | H12: - | I12: ○ | J12: No | K12: Yes | L12: 12 | M12: =SUMIFS(月次バックデータ!$H:$H,月次バックデータ!$B:$B,$B12,月次バックデータ!$E:$E,"グロス売上") -> 200 | N12: =SUMIFS(月次バックデータ!$I:$I,月次バックデータ!$B:$B,$B12,月次バックデータ!$E:$E,"グロス売上") -> 600 | O12: =SUMIFS(月次バックデータ!$J:$J,月次バックデータ!$B:$B,$B12,月次バックデータ!$E:$E,"グロス売上") -> 1100 | P12: =SUMIFS(月次バックデータ!$H:$H,月次バックデータ!$B:$B,$B12,月次バックデータ!$E:$E,"Sales Contribution") -> 200 | Q12: =SUMIFS(月次バックデータ!$I:$I,月次バックデータ!$B:$B,$B12,月次バックデータ!$E:$E,"Sales Contribution") -> 400 | R12: =SUMIFS(月次バックデータ!$J:$J,月次バックデータ!$B:$B,$B12,月次バックデータ!$E:$E,"Sales Contribution") -> 600 | S12: =IF(G12="○",VLOOKUP(F12,Practice別!B:O,14,FALSE),"-") -> 500 | T12: 1 | U12: 0.07 | V12: =ROUND(SUMIFS(月次バックデータ!$M:$M,月次バックデータ!$B:$B,$B12,月次バックデータ!$E:$E,"Sales Contribution"),0) -> 367 | W12: =$S12 -> 500 | X12: =IF(W12>V12,W12,V12) -> 500 | Y12: =V12 -> 367 | Z12: 0.4 | AA12: - | AB12: - | AC12: - | AD12: ・サイバーセキュリティ専門人材（CISO、SOC経験者等）を年間7名以上面談し、うち3名以上の内定承諾に貢献 ・セキュリティカンファレンスまたは採用セッションに2回以上参画 | AE12: ・新規クライアント含む3社において、CISOまたはセキュリティ責任者との四半期ごとの戦略対話を主導 ・サイバーセキュリティ脅威動向やガバナンス強化に関する情報提供セッションを年6回以上実施 | AF12: ・セキュリティ強化ニーズを持つ新規クライアント4社へのアプローチをリードし、うち2社でパイロット案件を受注 ・グローバルセキュリティ体制構築事例やSOC立ち上げ実績を活用した提案活動を実施 | AG12: ・サイバーセキュリティガバナンスに関する社内トレーニングを年3回開催 ・Practice内メンバー3名以上に対する定期的なメンタリングとスキル育成を実施 | AH12: ・サイバーセキュリティ戦略またはゼロトラストアーキテクチャに関するホワイトペーパーを年2本発信 ・セキュリティカンファレンスへの登壇を年2回以上実施し、Practice Leaderとしてのプレゼンスを確立 | AI12: =0.5/3 -> 0.16666667 | AJ12: =0.5/3 -> 0.16666667 | AK12: =0.5/3 -> 0.16666667 | AL12: - | AM12: - | AN12: =0.25/3 -> 0.083333333 | AO12: =0.25/3 -> 0.083333333 | AP12: =0.25/3 -> 0.083333333 | AQ12: 0.05 | AR12: 0.05 | AS12: 0.05 | AT12: 0.05 | AU12: 0.05 | AV12: =SUM(AI12:AU12) -> 1
B13: 藤澤 賢成 | C13: 45748 | D13: D | E13: Industry | F13: Financial Service | G13: ○ | H13: ○ | I13: ○ | J13: Yes | K13: Yes | L13: 12 | M13: =SUMIFS(月次バックデータ!$H:$H,月次バックデータ!$B:$B,$B13,月次バックデータ!$E:$E,"グロス売上") -> 200 | N13: =SUMIFS(月次バックデータ!$I:$I,月次バックデータ!$B:$B,$B13,月次バックデータ!$E:$E,"グロス売上") -> 400 | O13: =SUMIFS(月次バックデータ!$J:$J,月次バックデータ!$B:$B,$B13,月次バックデータ!$E:$E,"グロス売上") -> 600 | P13: =SUMIFS(月次バックデータ!$H:$H,月次バックデータ!$B:$B,$B13,月次バックデータ!$E:$E,"Sales Contribution") -> 200 | Q13: =SUMIFS(月次バックデータ!$I:$I,月次バックデータ!$B:$B,$B13,月次バックデータ!$E:$E,"Sales Contribution") -> 400 | R13: =SUMIFS(月次バックデータ!$J:$J,月次バックデータ!$B:$B,$B13,月次バックデータ!$E:$E,"Sales Contribution") -> 600 | S13: =IF(G13="○",VLOOKUP(F13,Practice別!B:O,14,FALSE),"-") -> 600 | T13: 1 | U13: 0.07 | V13: =ROUND(SUMIFS(月次バックデータ!$M:$M,月次バックデータ!$B:$B,$B13,月次バックデータ!$E:$E,"Sales Contribution"),0) -> 467 | W13: =$S13 -> 600 | X13: =IF(W13>V13,W13,V13) -> 600 | Y13: =V13 -> 467 | Z13: 0.5 | AA13: 三菱UFJ・野村HD | AB13: - | AC13: 400 | AD13: ・金融領域の専門人材を年間5名以上面談し、うち2名以上の内定承諾に貢献 | AE13: ・ターゲットアカウントにおいて、CROまたはCCOレベルとの四半期ごとの戦略ディスカッションを主導 ・金融規制動向やリスク管理高度化に関する情報提供セッションを年3回以上実施 | AF13: ・Basel規制対応やAML/CFT高度化ニーズを持つ新規金融機関2社へのアプローチをリードし、1件以上のパイロット案件を受注 ・金融当局動向レポートを活用した提案機会創出を四半期ごとに実施 | AG13: ・金融規制・リスク管理に関する社内勉強会を年1回以上開催し、ジュニアコンサルタントの専門性向上を支援 ・プロジェクトにおいて2名以上のメンバーへのOJT・メンタリングを実施し、金融規制対応スキルを伝達 | AH13: ・Basel規制やAML高度化に関するホワイトペーパーまたは業界誌への寄稿を年1本発信（上期1本、下期1本） ・金融規制セミナーへの登壇を年1回以上実施し、ファームの専門性を対外発信 | AI13: =0.25/3 -> 0.083333333 | AJ13: =0.25/3 -> 0.083333333 | AK13: =0.25/3 -> 0.083333333 | AL13: =0.25/2 -> 0.125 | AM13: =0.25/2 -> 0.125 | AN13: =0.25/3 -> 0.083333333 | AO13: =0.25/3 -> 0.083333333 | AP13: =0.25/3 -> 0.083333333 | AQ13: 0.05 | AR13: 0.05 | AS13: 0.05 | AT13: 0.05 | AU13: 0.05 | AV13: =SUM(AI13:AU13) -> 1
B14: 大塩 大輔 | C14: 46143 | D14: MD | E14: Industry | F14: Public | G14: ○ | H14: ○ | I14: ○ | J14: No | K14: Yes | L14: 12 | M14: =SUMIFS(月次バックデータ!$H:$H,月次バックデータ!$B:$B,$B14,月次バックデータ!$E:$E,"グロス売上") -> 200 | N14: =SUMIFS(月次バックデータ!$I:$I,月次バックデータ!$B:$B,$B14,月次バックデータ!$E:$E,"グロス売上") -> 400 | O14: =SUMIFS(月次バックデータ!$J:$J,月次バックデータ!$B:$B,$B14,月次バックデータ!$E:$E,"グロス売上") -> 600 | P14: =SUMIFS(月次バックデータ!$H:$H,月次バックデータ!$B:$B,$B14,月次バックデータ!$E:$E,"Sales Contribution") -> 200 | Q14: =SUMIFS(月次バックデータ!$I:$I,月次バックデータ!$B:$B,$B14,月次バックデータ!$E:$E,"Sales Contribution") -> 400 | R14: =SUMIFS(月次バックデータ!$J:$J,月次バックデータ!$B:$B,$B14,月次バックデータ!$E:$E,"Sales Contribution") -> 600 | S14: =IF(G14="○",VLOOKUP(F14,Practice別!B:O,14,FALSE),"-") -> 1440 | T14: 1 | U14: 0.07 | V14: =ROUND(SUMIFS(月次バックデータ!$M:$M,月次バックデータ!$B:$B,$B14,月次バックデータ!$E:$E,"Sales Contribution"),0) -> 250 | W14: =$S14/18*6 -> 480 | X14: =IF(W14>V14,W14,V14) -> 480 | Y14: =V14 -> 250 | Z14: 0.4 | AA14: 国税庁・協会けんぽ | AB14: - | AC14: 296 | AD14: ・官公庁・公共セクター経験者（官公庁出身者、公共系コンサルタント等）を年間7名以上面談し、うち3名以上の内定承諾に貢献 ・公共セクター向けキャリアセミナーまたは採用イベントに2回以上参画 | AE14: ・既存クライアント（国税庁・協会けんぽ）含む3機関において、局長・部長または理事レベルとの四半期ごとの戦略対話を主導 ・行政DX、税務・社会保険行政のデジタル化、ガバメントクラウド等に関する情報提供セッションを年6回以上実施 | AF14: ・新規中央省庁・独立行政法人・自治体4機関へのアプローチをリードし、うち2機関で案件を受注 ・政策動向を踏まえた入札案件の早期把握と事前提案（RFI対応・企画提案）を実施 | AG14: ・官公庁ビジネス（調達・入札プロセス、政策立案支援）に関する社内トレーニングを年3回開催 ・Practice内メンバー3名以上に対する定期的なメンタリングとフィードバックを実施 | AH14: ・行政DXまたは公共サービス改革に関するホワイトペーパーを年2本発信 ・公共政策フォーラムまたは官公庁向けセミナーへの登壇を年2回以上実施し、Practice Leaderとしてのプレゼンスを確立 | AI14: =0.25/3 -> 0.083333333 | AJ14: =0.25/3 -> 0.083333333 | AK14: =0.25/3 -> 0.083333333 | AL14: =0.25/2 -> 0.125 | AM14: =0.25/2 -> 0.125 | AN14: =0.25/3 -> 0.083333333 | AO14: =0.25/3 -> 0.083333333 | AP14: =0.25/3 -> 0.083333333 | AQ14: 0.05 | AR14: 0.05 | AS14: 0.05 | AT14: 0.05 | AU14: 0.05 | AV14: =SUM(AI14:AU14) -> 1
B15: 石川 利一 | C15: 45931 | D15: D | E15: Industry | F15: Public | G15: - | H15: ○ | I15: ○ | J15: No | K15: Yes | L15: 12 | M15: - | N15: - | O15: - | P15: =SUMIFS(月次バックデータ!$H:$H,月次バックデータ!$B:$B,$B15,月次バックデータ!$E:$E,"Sales Contribution") -> 275 | Q15: =SUMIFS(月次バックデータ!$I:$I,月次バックデータ!$B:$B,$B15,月次バックデータ!$E:$E,"Sales Contribution") -> 700 | R15: =SUMIFS(月次バックデータ!$J:$J,月次バックデータ!$B:$B,$B15,月次バックデータ!$E:$E,"Sales Contribution") -> 1500 | S15: =IF(G15="○",VLOOKUP(F15,Practice別!B:O,14,FALSE),"-") -> - | T15: - | U15: - | V15: =ROUND(SUMIFS(月次バックデータ!$M:$M,月次バックデータ!$B:$B,$B15,月次バックデータ!$E:$E,"Sales Contribution"),0) -> 629 | W15: =$S14/18*4 -> 320 | X15: =IF(W15>V15,W15,V15) -> 629 | Y15: - | Z15: - | AA15: 厚生労働省 | AB15: - | AC15: 311 | AD15: ・アバナードメンバーのスムーズな転籍プログラムの実行 | AE15: ・官公庁または公共機関の既存クライアント2機関において、部局長レベルとの定期的なリレーション活動を実施 ・行政DXや社会保障制度改革に関する情報提供セッションを年3回以上実施 | AF15: ・新規官公庁または自治体2機関へのアプローチをリードし、1件以上のプロジェクトを受注 ・政策動向レポートや先進事例紹介を活用した提案活動を実施 | AG15: ・官公庁ビジネスの特性や年金・社会保障制度に関する社内勉強会を年2回開催 ・公共セクタープロジェクトにおいて2名以上のメンバーへの実務指導を実施 | AH15: ・行政DXまたは社会保障政策に関する論考を年1本発信 ・公共政策フォーラムまたは自治体向けセミナーへの登壇を年1回以上実施 | AI15: - | AJ15: - | AK15: - | AL15: =0.5/2 -> 0.25 | AM15: =0.5/2 -> 0.25 | AN15: 0.25 | AO15: - | AP15: - | AQ15: 0.05 | AR15: 0.05 | AS15: 0.05 | AT15: 0.05 | AU15: 0.05 | AV15: =SUM(AI15:AU15) -> 1
B16: 玉井 俊行 | C16: 46054 | D16: D | E16: Industry | F16: Public | G16: - | H16: ○ | I16: ○ | J16: No | K16: Yes | L16: 12 | M16: - | N16: - | O16: - | P16: =SUMIFS(月次バックデータ!$H:$H,月次バックデータ!$B:$B,$B16,月次バックデータ!$E:$E,"Sales Contribution") -> 200 | Q16: =SUMIFS(月次バックデータ!$I:$I,月次バックデータ!$B:$B,$B16,月次バックデータ!$E:$E,"Sales Contribution") -> 400 | R16: =SUMIFS(月次バックデータ!$J:$J,月次バックデータ!$B:$B,$B16,月次バックデータ!$E:$E,"Sales Contribution") -> 600 | S16: =IF(G16="○",VLOOKUP(F16,Practice別!B:O,14,FALSE),"-") -> - | T16: - | U16: - | V16: =ROUND(SUMIFS(月次バックデータ!$M:$M,月次バックデータ!$B:$B,$B16,月次バックデータ!$E:$E,"Sales Contribution"),0) -> 300 | W16: =$S14/18*4 -> 320 | X16: =IF(W16>V16,W16,V16) -> 320 | Y16: =V16 -> 300 | Z16: 0.5 | AA16: 農林水産省・国土交通省・経済産業省 | AB16: - | AC16: 713 | AD16: ・官公庁・公共セクター領域の経験者を年間5名以上面談し、うち2名以上の内定承諾に貢献 | AE16: ・既存クライアント（農林水産省・国土交通省・経済産業省）において、課長・室長レベルとの定期的なリレーション活動を実施 ・産業政策、インフラDX、食料・農業政策動向に関する情報提供セッションを年3回以上実施 | AF16: ・新規省庁または関連独立行政法人2機関へのアプローチをリードし、1件以上のプロジェクトを受注 ・政策動向レポートや先進事例紹介を活用した提案活動を実施 | AG16: ・官公庁の調査・実証事業の進め方に関する社内勉強会を年2回開催 ・公共セクタープロジェクトにおいて2名以上のメンバーへの実務指導を実施 | AH16: ・産業政策またはインフラDXに関する論考を年1本発信 ・公共政策フォーラムまたは自治体・業界団体向けセミナーへの登壇を年1回以上実施 | AI16: - | AJ16: - | AK16: - | AL16: =0.5/2 -> 0.25 | AM16: =0.5/2 -> 0.25 | AN16: =0.25/3 -> 0.083333333 | AO16: =0.25/3 -> 0.083333333 | AP16: =0.25/3 -> 0.083333333 | AQ16: 0.05 | AR16: 0.05 | AS16: 0.05 | AT16: 0.05 | AU16: 0.05 | AV16: =SUM(AI16:AU16) -> 1
